Workbook

Sheet Dashboard
A1: Team-III 每週工作報告 | 2026 W37 ｜ Dashboard
A2: 報告說明：本檔為 Anderson KM 精確度／Rerank 補登獨立版本；其他成員頁籤保留原始資料作參照。
A3: # | B3: 任務 | C3: 負責人 | D3: 優先 | E3: 進度 | F3: 交付至（SharePoint） | G3: 備註
A4: T1 Agent開發進度更新
A5: Anderson | B5: 追蹤L3~L5各模組開發里程碑與整合進度 | C5: Anderson | D5: High | E5: =Anderson!$G$5 | F5: 驗證三部/Agent AI導入計劃_Sam | G5: 每週追蹤開發里程碑
A6: Patty | B6: 同步Amarisoft/Anritsu設備Agent整合進度 | C6: Patty | D6: High | E6: =Patty!$G$5 | F6: 驗證三部/Agent AI導入計劃_Sam | G6: 每週追蹤開發里程碑
A8: T2 POC結束後優先導入哪個Agent評估環境之討論
A9: Sam | B9: 主持討論並確認戰略方向 | C9: Sam | D9: High | E9: =Sam!$G$5 | F9: 驗證三部/專案計畫 | G9: 等待POC結束後啟動
A10: Patty | B10: 提供設備端視角與可行性評估 | C10: Patty | D10: High | E10: =Patty!$G$8 | F10: 驗證三部/Agent AI導入計劃_Sam | G10: 等待POC結束後啟動
A11: Anderson | B11: 提供系統整合視角與風險分析 | C11: Anderson | D11: High | E11: =Anderson!$G$8 | F11: 驗證三部/Agent AI導入計劃_Sam | G11: 等待POC結束後啟動
A13: T3 CSIT System驗證申請系統
A14: Patty | B14: 系統設計、開發、測試與上線維運 | C14: Patty | D14: Mid | E14: =Patty!$G$11 | F14: 驗證三部/專案計畫 | G14: 建置與優化CSIT系統驗證申請流程
A16: T4 設備預約系統
A17: Patty | B17: 系統維運、功能改進與異常處理 | C17: Patty | D17: Mid | E17: =Patty!$G$14 | F17: 驗證三部/專案計畫 | G17: 設備預約系統日常維運
A19: T5 KM資料庫優化
A20: Patty | B20: Neo4j圖譜結構與節點分類優化 | C20: Patty | D20: Mid | E20: =Patty!$G$17 | F20: 驗證三部/KM | G20: Neo4j + Qdrant 效能調校
A21: Anderson | B21: Qdrant向量索引、Rerank與檢索評分驗證 | C21: Anderson | D21: Mid | E21: 90 | F21: 驗證三部/KM | G21: Qwen3 active；評分可呈現；Golden qrels 尚待補齊
A23: T6 LLM選型
A24: Jimmy | B24: 評估候選模型、制定評估指標與基準測試 | C24: Jimmy | D24: Mid | E24: =Jimmy!$G$5 | F24: 驗證三部/AI訓練教材-L3 | G24: 評估並選定適合FDE的LLM模型
A25: Alf | B25: 整合評估結果與成本效益分析 | C25: Alf | D25: Mid | E25: =Alf!$G$5 | F25: 驗證三部/AI訓練教材-L3 | G25: 評估並選定適合FDE的LLM模型
A27: T7 評估openVitamin功能分析
A28: Alf | B28: 工具鏈分析與整合可行性評估 | C28: Alf | D28: Mid | E28: =Alf!$G$8 | F28: 驗證三部/AI訓練教材-L3 | G28: 分析openVitamin工具鏈與整合可行性
A29: Jimmy | B29: 技術對接與風險識別 | C29: Jimmy | D29: Mid | E29: =Jimmy!$G$8 | F29: 驗證三部/AI訓練教材-L3 | G29: 分析openVitamin工具鏈與整合可行性
A31: T8 Sub2Api建置
A32: Alf | B32: API架構設計、開發與文件編寫 | C32: Alf | D32: Mid | E32: =Alf!$G$11 | F32: 驗證三部/專案計畫 | G32: 建立Sub2Api接口服務

Sheet Patty
A1: Team-III 個人週報 ｜ Patty ｜ 2026 July
A2: ▸ 請填寫「預計完成日」「實際完成日」「進度(%)」「交付路徑」，進度將連動至Dashboard ▸ T# 編號對應開發計劃分頁，請與開發計劃進度保持一致 ▸ 有不在專案開發計劃的工作，請自行新增於下方額外任務區 ▸ 完成後請上傳至SharePoint | K2: ▸ 本週的關鍵技術判斷？為什麼這樣決定？ | L2: ▸ 本週否決過AI的哪個建議？為什麼？
A3: 任務群組 | B3: T# | C3: 任務 | D3: 預計完成日 | E3: 實際完成日 | F3: 進度狀態 | G3: 進度(%) | H3: 交付至（SharePoint） | I3: 交付路徑 | J3: 備註 | K3: 關鍵判斷 | L3: 否決AI記錄
A4: T1
B5: T1 | C5: 同步Amarisoft/Anritsu設備Agent整合進度 | D5: 2026-08-15 | G5: 60 | H5: 驗證三部/Agent AI導入計劃_Sam | J5: 每週追蹤開發里程碑
A6: T1-B1
B7: T1-B1 | C7: 對話流程設計（Amarisoft設備Agent） | D7: 2026-08-22 | G7: 0 | H7: 驗證三部/Agent AI導入計劃_Sam | J7: T1 設備整合
A8: T1-B2
B9: T1-B2 | C9: 異常處理流程（Anritsu設備Agent） | D9: 2026-08-25 | G9: 0 | H9: 驗證三部/Agent AI導入計劃_Sam | J9: T1 設備整合
A10: T1-C1
B11: T1-C1 | C11: 設備預約模組串接 | D11: 2026-08-28 | G11: 0 | H11: 驗證三部/Agent AI導入計劃_Sam | J11: T1 設備整合
A12: T1-C2
B13: T1-C2 | C13: 設備狀態查詢模組串接 | D13: 2026-08-30 | G13: 0 | H13: 驗證三部/Agent AI導入計劃_Sam | J13: T1 設備整合
A14: T3
B15: T3 | C15: 系統設計、開發、測試與上線維運 | D15: 2026-09-30 | G15: 40 | H15: 驗證三部/專案計畫 | J15: T3 CSIT System 全權負責
A16: T3-A1
B17: T3-A1 | C17: CSIT系統架構設計 | D17: 2026-08-25 | G17: 0 | H17: 驗證三部/專案計畫 | J17: T3 系統開發
A18: T3-A2
B19: T3-A2 | C19: 資料庫設計 | D19: 2026-09-01 | G19: 0 | H19: 驗證三部/專案計畫 | J19: T3 系統開發
A20: T3-B1
B21: T3-B1 | C21: 申請流程設計 | D21: 2026-09-05 | G21: 0 | H21: 驗證三部/專案計畫 | J21: T3 系統開發
A22: T3-B2
B23: T3-B2 | C23: 審核流程設計 | D23: 2026-09-08 | G23: 0 | H23: 驗證三部/專案計畫 | J23: T3 系統開發
A24: T4
B25: T4 | C25: 系統維運、功能改進與異常處理 | D25: 2026-12-31 | G25: 50 | H25: 驗證三部/專案計畫 | J25: T4 設備預約系統 全權負責
A26: T4-A1
B27: T4-A1 | C27: 設備預約系統架構設計 | D27: 2026-08-25 | G27: 0 | H27: 驗證三部/專案計畫 | J27: T4 設備預約系統
A28: T5-B1
B29: T5-B1 | C29: 知識入庫流程設計 | D29: 2026-09-05 | G29: 0 | H29: 驗證三部/KM | J29: T5 KM 優化
A30: T5-K2
B31: T5-K2 | C31: 專家經驗收集 | D31: 2026-08-22 | G31: 0 | H31: 驗證三部/KM | J31: T5 KM 優化
A33: 【額外任務 - 不在專案開發計劃範圍，請自行新增】
B34: E01 | G34: 0
B35: E02 | G35: 0
B36: E03 | G36: 0
B37: E04 | G37: 0
B38: E05 | G38: 0
B39: E06 | G39: 0
B40: E07 | G40: 0
B41: E08 | G41: 0

Sheet Anderson
A1: Team-III 個人週報 ｜ Anderson ｜ 2026 W37（KM 精確度／Rerank 補登）
A2: 本份僅記錄 KM 文件精確度評分、Rerank、lifecycle hard filter 與 fallback 驗證；CSIT 工作另列 W38。 | K2: ▸ 本週的關鍵技術判斷？為什麼這樣決定？ | L2: ▸ 本週否決過AI的哪個建議？為什麼？
A3: 任務群組 | B3: T# | C3: 任務 | D3: 預計完成日 | E3: 實際完成日 | F3: 進度狀態 | G3: 進度(%) | H3: 交付至（SharePoint） | I3: 交付路徑 | J3: 備註 | K3: 關鍵判斷 | L3: 否決AI記錄
A4: W37 補登｜KM 搜尋精確度與 Rerank
A5: KM整合工作 | B5: KM-W37-01 | C5: 文件精確度評分與離線 evaluator | D5: 2026 Q4 | F5: 已完成第一版／Golden qrels 待補 | G5: 85 | H5: 驗證三部/KM | I5: score breakdown、Recall/Precision/MRR/nDCG 設計 | J5: 分數是排序／品質訊號，不宣稱答案正確率 | K5: 不以單一分數取代多項指標
A7: KM整合工作 | B7: KM-W37-02 | C7: Qwen3-Reranker-0.6B 整合與 fallback | D7: 2026 Q4 | F7: RUNTIME_VALIDATED | G7: 90 | H7: 驗證三部/KM | I7: PR #57；Qwen3 model identity；active search task | J7: hard filter → rerank；異常回退 baseline | K7: 不以模型可載入取代搜尋成效驗收
A9: KM整合工作 | B9: KM-W37-03 | C9: 真實搜尋來源卡評分呈現 | D9: 2026 Q4 | F9: USER_VISIBLE_VALIDATED | G9: 90 | H9: 驗證三部/KM | I9: chat.html／Vue score markers | J9: 評分與 citation/source 綁定呈現 | K9: 不新增無來源答案正確率
A11: KM整合工作 | B11: KM-W37-04 | C11: Lifecycle hard filter 與受控 reindex | D11: 2026 Q4 | F11: RUNTIME_VALIDATED | G11: 100 | H11: 驗證三部/KM | I11: 4,001 points；mismatch=0 | J11: Draft／非 current 不進 rerank | K11: 不讓分數抵銷 ACL/lifecycle

Sheet Jimmy
A1: Team-III 個人週報 ｜ Jimmy ｜ 2026 July
A2: ▸ 請填寫「預計完成日」「實際完成日」「進度(%)」「交付路徑」，進度將連動至Dashboard ▸ T# 編號對應開發計劃分頁，請與開發計劃進度保持一致 ▸ 有不在專案開發計劃的工作，請自行新增於下方額外任務區 ▸ 完成後請上傳至SharePoint | K2: ▸ 本週的關鍵技術判斷？為什麼這樣決定？ | L2: ▸ 本週否決過AI的哪個建議？為什麼？
A3: 任務群組 | B3: T# | C3: 任務 | D3: 預計完成日 | E3: 實際完成日 | F3: 進度狀態 | G3: 進度(%) | H3: 交付至（SharePoint） | I3: 交付路徑 | J3: 備註 | K3: 關鍵判斷 | L3: 否決AI記錄
A4: T6
B5: T6 | C5: 評估候選模型、制定評估指標與基準測試 | D5: 2026-08-31 | G5: 30 | H5: 驗證三部/AI訓練教材-L3 | J5: T6 LLM選型
A6: T6-A1
B7: T6-A1 | C7: LLM評估架構設計 | D7: 2026-08-20 | G7: 0 | H7: 驗證三部/AI訓練教材-L3 | J7: T6 LLM選型
A8: T6-B1
B9: T6-B1 | C9: 評估流程設計 | D9: 2026-08-25 | G9: 0 | H9: 驗證三部/AI訓練教材-L3 | J9: T6 LLM選型
A10: T6-K1
B11: T6-K1 | C11: 評估指標訪談（設備/測試團隊） | D11: 2026-08-15 | G11: 0 | H11: 驗證三部/AI訓練教材-L3 | J11: T6 LLM選型
A12: T6-K3
B13: T6-K3 | C13: 使用情境訪談 | D13: 2026-08-25 | G13: 0 | H13: 驗證三部/AI訓練教材-L3 | J13: T6 LLM選型
A14: T7
B15: T7 | C15: 技術對接與風險識別（OpenVitamin） | D15: 2026-08-31 | G15: 30 | H15: 驗證三部/AI訓練教材-L3 | J15: T7 OpenVitamin 評估
A16: T7-06
B17: T7-06 | C17: 與內部系統整合架構規劃 | D17: 2026-08-15 | G17: 50 | H17: 驗證三部/AI訓練教材-L3 | J17: T7 技術評估
A18: T7-07
B19: T7-07 | C19: 五大應用場景流程設計 | D19: 2026-08-15 | G19: 60 | H19: 驗證三部/AI訓練教材-L3 | J19: T7 技術評估
A20: T10
B21: T10 | C21: AI工具操作訓練（Neo4j/Qdrant） | D21: 2026-09-15 | G21: 0 | H21: 驗證三部/教育訓練 | J21: T10 教育訓練
A23: 【額外任務 - 不在專案開發計劃範圍，請自行新增】
B24: E01 | G24: 0
B25: E02 | G25: 0
B26: E03 | G26: 0
B27: E04 | G27: 0
B28: E05 | G28: 0
B29: E06 | G29: 0
B30: E07 | G30: 0
B31: E08 | G31: 0

Sheet Alf
A1: Team-III 個人週報 ｜ Alf ｜ 2026 July
A2: ▸ 請填寫「預計完成日」「實際完成日」「進度(%)」「交付路徑」，進度將連動至Dashboard ▸ T# 編號對應開發計劃分頁，請與開發計劃進度保持一致 ▸ 有不在專案開發計劃的工作，請自行新增於下方額外任務區 ▸ 完成後請上傳至SharePoint | K2: ▸ 本週的關鍵技術判斷？為什麼這樣決定？ | L2: ▸ 本週否決過AI的哪個建議？為什麼？
A3: 任務群組 | B3: T# | C3: 任務 | D3: 預計完成日 | E3: 實際完成日 | F3: 進度狀態 | G3: 進度(%) | H3: 交付至（SharePoint） | I3: 交付路徑 | J3: 備註 | K3: 關鍵判斷 | L3: 否決AI記錄
A4: T6-B2
B5: T6-B2 | C5: 成本效益分析流程設計 | D5: 2026-08-28 | G5: 0 | H5: 驗證三部/AI訓練教材-L3 | J5: T6 LLM選型
A6: T6-K2
B7: T6-K2 | C7: 候選模型文件收集 | D7: 2026-08-20 | G7: 0 | H7: 驗證三部/AI訓練教材-L3 | J7: T6 LLM選型
A8: T7
B9: T7 | C9: 工具鏈分析與整合可行性評估 | D9: 2026-08-31 | G9: 30 | H9: 驗證三部/AI訓練教材-L3 | J9: T7 OpenVitamin 全權負責
A10: T7-01
B11: T7-01 | C11: OpenVitamin 系統功能模組分析 | D11: 2026-08-08 | G11: 60 | H11: 驗證三部/AI訓練教材-L3 | J11: T7 技術評估
A12: T7-02
B13: T7-02 | C13: 原生架構深度分析 | D13: 2026-08-12 | G13: 50 | H13: 驗證三部/AI訓練教材-L3 | J13: T7 技術評估
A14: T7-03
B15: T7-03 | C15: 與內部系統整合架構規劃 | D15: 2026-08-15 | G15: 50 | H15: 驗證三部/AI訓練教材-L3 | J15: T7 技術評估
A16: T7-04
B17: T7-04 | C17: OpenVitamin vs 未來幢平台 vs 自建方案 | D17: 2026-08-19 | G17: 40 | H17: 驗證三部/AI訓練教材-L3 | J17: T7 技術評估
A18: T7-05
B19: T7-05 | C19: 五大應用場景流程設計 | D19: 2026-08-15 | G19: 60 | H19: 驗證三部/AI訓練教材-L3 | J19: T7 技術評估
A20: T8
B21: T8 | C21: API架構設計、開發與文件編寫 | D21: 2026-09-30 | G21: 20 | H21: 驗證三部/專案計畫 | J21: T8 Sub2Api 全權負責
A22: T8-01
B23: T8-01 | C23: Sub2Api系統架構規劃 | D23: 2026-08-05 | G23: 70 | H23: 驗證三部/專案計畫 | J23: T8 Sub2Api
A24: T8-02
B25: T8-02 | C25: REST API規格定義 | D25: 2026-08-08 | G25: 70 | H25: 驗證三部/專案計畫 | J25: T8 Sub2Api
A26: T8-03
B27: T8-03 | C27: 資料模型設計 | D27: 2026-08-08 | G27: 60 | H27: 驗證三部/專案計畫 | J27: T8 Sub2Api
A28: T8-04
B29: T8-04 | C29: API處理流程設計 | D29: 2026-08-10 | G29: 60 | H29: 驗證三部/專案計畫 | J29: T8 Sub2Api
A30: T8-05
B31: T8-05 | C31: 認證授權流程設計 | D31: 2026-08-10 | G31: 60 | H31: 驗證三部/專案計畫 | J31: T8 Sub2Api
A33: 【額外任務 - 不在專案開發計劃範圍，請自行新增】
B34: E01 | G34: 0
B35: E02 | G35: 0
B36: E03 | G36: 0
B37: E04 | G37: 0
B38: E05 | G38: 0
B39: E06 | G39: 0
B40: E07 | G40: 0
B41: E08 | G41: 0

Sheet Sam
A1: Team-III 個人週報 ｜ Sam ｜ 2026 July
A2: ▸ 請填寫「預計完成日」「實際完成日」「進度(%)」「交付路徑」，進度將連動至Dashboard ▸ T# 編號對應開發計劃分頁，請與開發計劃進度保持一致 ▸ 有不在專案開發計劃的工作，請自行新增於下方額外任務區 ▸ 完成後請上傳至SharePoint | K2: ▸ 本週的關鍵技術判斷？為什麼這樣決定？ | L2: ▸ 本週否決過AI的哪個建議？為什麼？
A3: 任務群組 | B3: T# | C3: 任務 | D3: 預計完成日 | E3: 實際完成日 | F3: 進度狀態 | G3: 進度(%) | H3: 交付至（SharePoint） | I3: 交付路徑 | J3: 備註 | K3: 關鍵判斷 | L3: 否決AI記錄
A4: T2
B5: T2 | C5: 主持討論並確認戰略方向 | D5: 2026-08-31 | G5: 30 | H5: 驗證三部/專案計畫 | J5: 等待POC結束後啟動
A6: T2-A1
B7: T2-A1 | C7: 評估環境架構規劃 | D7: 2026-08-20 | G7: 0 | H7: 驗證三部/專案計畫 | J7: T2 戰略討論
A8: T2-B1
B9: T2-B1 | C9: 決策流程設計 | D9: 2026-08-22 | G9: 0 | H9: 驗證三部/專案計畫 | J9: T2 戰略討論
A10: T2-K1
B11: T2-K1 | C11: 利害關係人需求訪談 | D11: 2026-08-15 | G11: 0 | H11: 驗證三部/專案計畫 | J11: T2 需求訪談
A12: T10
B13: T10 | C13: 部門AI導入策略與資源協調 | D13: 2026-09-30 | G13: 0 | H13: 驗證三部/教育訓練 | J13: T10 教育訓練統籌
A15: 【額外任務 - 不在專案開發計劃範圍，請自行新增】
B16: E01 | G16: 0
B17: E02 | G17: 0
B18: E03 | G18: 0
B19: E04 | G19: 0
B20: E05 | G20: 0
B21: E06 | G21: 0
B22: E07 | G22: 0
B23: E08 | G23: 0

Sheet T1開發計劃
A1: T1開發計劃｜Agent開發進度更新
A2: 負責人：Anderson, Patty ｜ 建立日期：2026-07-31 | M2: ▸ 請填入實際檔案路徑或 SharePoint 連結 | N2: ▸ 本週的關鍵技術判斷？為什麼這樣決定？ | O2: ▸ 本週否決過AI的哪個建議？為什麼？
A3: 階段 | B3: 子階段 | C3: 任務編號 | D3: 任務名稱 | E3: 任務說明 | F3: 交付產出 | G3: 負責人 | H3: 預計完成日 | I3: 實際完成日 | J3: 開發狀態 | K3: 進度(%) | L3: 備註 | M3: 交付路徑 | N3: 關鍵判斷 | O3: 否決AI記錄
A4: 系統架構設計
A5: 系統架構設計 | B5: 架構規劃 | C5: T1-A1 | D5: 系統架構規劃 | E5: 整體多層Agent架構設計，包含L1-L5分層定義與職責分工 | F5: 系統架構圖文件 | G5: Anderson | H5: 2026-08-15 | J5: =IF(I5<>"", IF(I5>DATEVALUE(H5),"🔴 逾期 "&(I5-DATEVALUE(H5))&"天", IF(DATEVALUE(H5)>I5,"🟢 提前 "&(DATEVALUE(H5)-I5)&"天","🟡 準時完成")), IF((DATEVALUE(H5)-TODAY())<=3,"🟡 接近截止（"&(DATEVALUE(H5)-TODAY())&"天）", IF(TODAY()>DATEVALUE(H5),"🔴 逾期 "&(TODAY()-DATEVALUE(H5))&"天（未完成）","🟢 " &(DATEVALUE(H5)-TODAY())&"天後到期"))) | K5: 0
A6: 系統架構設計 | B6: 架構規劃 | C6: T1-A2 | D6: 技術選型評估 | E6: 評估Neo4j/Qdrant/對話引擎技術可行性 | F6: 技術評估報告 | G6: Anderson | H6: 2026-08-20 | J6: =IF(I6<>"", IF(I6>DATEVALUE(H6),"🔴 逾期 "&(I6-DATEVALUE(H6))&"天", IF(DATEVALUE(H6)>I6,"🟢 提前 "&(DATEVALUE(H6)-I6)&"天","🟡 準時完成")), IF((DATEVALUE(H6)-TODAY())<=3,"🟡 接近截止（"&(DATEVALUE(H6)-TODAY())&"天）", IF(TODAY()>DATEVALUE(H6),"🔴 逾期 "&(TODAY()-DATEVALUE(H6))&"天（未完成）","🟢 " &(DATEVALUE(H6)-TODAY())&"天後到期"))) | K6: 0
A7: 系統流程設計
A8: 系統流程設計 | B8: 流程設計 | C8: T1-B1 | D8: 對話流程設計 | E8: User→L1→L2→L3/L4/L5流程與路由邏輯 | F8: 流程圖文件 | G8: Patty | H8: 2026-08-22 | J8: =IF(I8<>"", IF(I8>DATEVALUE(H8),"🔴 逾期 "&(I8-DATEVALUE(H8))&"天", IF(DATEVALUE(H8)>I8,"🟢 提前 "&(DATEVALUE(H8)-I8)&"天","🟡 準時完成")), IF((DATEVALUE(H8)-TODAY())<=3,"🟡 接近截止（"&(DATEVALUE(H8)-TODAY())&"天）", IF(TODAY()>DATEVALUE(H8),"🔴 逾期 "&(TODAY()-DATEVALUE(H8))&"天（未完成）","🟢 " &(DATEVALUE(H8)-TODAY())&"天後到期"))) | K8: 0
A9: 系統流程設計 | B9: 流程設計 | C9: T1-B2 | D9: 異常處理流程 | E9: L4異常分析與升級流程設計 | F9: 異常處理流程圖 | G9: Patty | H9: 2026-08-25 | J9: =IF(I9<>"", IF(I9>DATEVALUE(H9),"🔴 逾期 "&(I9-DATEVALUE(H9))&"天", IF(DATEVALUE(H9)>I9,"🟢 提前 "&(DATEVALUE(H9)-I9)&"天","🟡 準時完成")), IF((DATEVALUE(H9)-TODAY())<=3,"🟡 接近截止（"&(DATEVALUE(H9)-TODAY())&"天）", IF(TODAY()>DATEVALUE(H9),"🔴 逾期 "&(TODAY()-DATEVALUE(H9))&"天（未完成）","🟢 " &(DATEVALUE(H9)-TODAY())&"天後到期"))) | K9: 0
A10: 知識工程與需求訪談
A11: 知識工程與需求訪談 | B11: 需求訪談 | C11: T1-K1 | D11: 專家訪談規劃 | E11: Matt/Issa設備操作情境訪談 | F11: 訪談大綱與問題清單 | G11: Anderson | H11: 2026-08-10 | J11: =IF(I11<>"", IF(I11>DATEVALUE(H11),"🔴 逾期 "&(I11-DATEVALUE(H11))&"天", IF(DATEVALUE(H11)>I11,"🟢 提前 "&(DATEVALUE(H11)-I11)&"天","🟡 準時完成")), IF((DATEVALUE(H11)-TODAY())<=3,"🟡 接近截止（"&(DATEVALUE(H11)-TODAY())&"天）", IF(TODAY()>DATEVALUE(H11),"🔴 逾期 "&(TODAY()-DATEVALUE(H11))&"天（未完成）","🟢 " &(DATEVALUE(H11)-TODAY())&"天後到期"))) | K11: 0
A12: 知識工程與需求訪談 | B12: 需求訪談 | C12: T1-K2 | D12: 設備參數矩陣建立 | E12: Amarisoft/Anritsu設備參數矩陣建立 | F12: 設備參數矩陣文件 | G12: Patty | H12: 2026-08-18 | J12: =IF(I12<>"", IF(I12>DATEVALUE(H12),"🔴 逾期 "&(I12-DATEVALUE(H12))&"天", IF(DATEVALUE(H12)>I12,"🟢 提前 "&(DATEVALUE(H12)-I12)&"天","🟡 準時完成")), IF((DATEVALUE(H12)-TODAY())<=3,"🟡 接近截止（"&(DATEVALUE(H12)-TODAY())&"天）", IF(TODAY()>DATEVALUE(H12),"🔴 逾期 "&(TODAY()-DATEVALUE(H12))&"天（未完成）","🟢 " &(DATEVALUE(H12)-TODAY())&"天後到期"))) | K12: 0
A13: 知識工程與需求訪談 | B13: 需求訪談 | C13: T1-K3 | D13: 現有SOP收集與數位化 | E13: 收集並數位化現有操作SOP文檔 | F13: 數位化SOP文件 | G13: Anderson | H13: 2026-08-25 | J13: =IF(I13<>"", IF(I13>DATEVALUE(H13),"🔴 逾期 "&(I13-DATEVALUE(H13))&"天", IF(DATEVALUE(H13)>I13,"🟢 提前 "&(DATEVALUE(H13)-I13)&"天","🟡 準時完成")), IF((DATEVALUE(H13)-TODAY())<=3,"🟡 接近截止（"&(DATEVALUE(H13)-TODAY())&"天）", IF(TODAY()>DATEVALUE(H13),"🔴 逾期 "&(TODAY()-DATEVALUE(H13))&"天（未完成）","🟢 " &(DATEVALUE(H13)-TODAY())&"天後到期"))) | K13: 0
A14: 開發現迭代任務
A15: 開發現迭代任務 | B15: 開發任務 | C15: T1-D1 | D15: L3 Supervisor Agent實作 | E15: L3 Supervisor Agent程式開發與單元測試 | F15: L3 Agent程式碼 | G15: Anderson | H15: 2026-09-05 | J15: =IF(I15<>"", IF(I15>DATEVALUE(H15),"🔴 逾期 "&(I15-DATEVALUE(H15))&"天", IF(DATEVALUE(H15)>I15,"🟢 提前 "&(DATEVALUE(H15)-I15)&"天","🟡 準時完成")), IF((DATEVALUE(H15)-TODAY())<=3,"🟡 接近截止（"&(DATEVALUE(H15)-TODAY())&"天）", IF(TODAY()>DATEVALUE(H15),"🔴 逾期 "&(TODAY()-DATEVALUE(H15))&"天（未完成）","🟢 " &(DATEVALUE(H15)-TODAY())&"天後到期"))) | K15: 0
A16: 開發現迭代任務 | B16: 開發任務 | C16: T1-D2 | D16: L4異常分析Agent實作 | E16: L4異常分析Agent實作與優化 | F16: L4 Agent程式碼 | G16: Anderson | H16: 2026-09-10 | J16: =IF(I16<>"", IF(I16>DATEVALUE(H16),"🔴 逾期 "&(I16-DATEVALUE(H16))&"天", IF(DATEVALUE(H16)>I16,"🟢 提前 "&(DATEVALUE(H16)-I16)&"天","🟡 準時完成")), IF((DATEVALUE(H16)-TODAY())<=3,"🟡 接近截止（"&(DATEVALUE(H16)-TODAY())&"天）", IF(TODAY()>DATEVALUE(H16),"🔴 逾期 "&(TODAY()-DATEVALUE(H16))&"天（未完成）","🟢 " &(DATEVALUE(H16)-TODAY())&"天後到期"))) | K16: 0
A17: 開發現迭代任務 | B17: 開發任務 | C17: T1-D3 | D17: Amarisoft設備Agent實作 | E17: Amarisoft設備Agent實作 | F17: Amarisoft Agent程式碼 | G17: Patty | H17: 2026-09-12 | J17: =IF(I17<>"", IF(I17>DATEVALUE(H17),"🔴 逾期 "&(I17-DATEVALUE(H17))&"天", IF(DATEVALUE(H17)>I17,"🟢 提前 "&(DATEVALUE(H17)-I17)&"天","🟡 準時完成")), IF((DATEVALUE(H17)-TODAY())<=3,"🟡 接近截止（"&(DATEVALUE(H17)-TODAY())&"天）", IF(TODAY()>DATEVALUE(H17),"🔴 逾期 "&(TODAY()-DATEVALUE(H17))&"天（未完成）","🟢 " &(DATEVALUE(H17)-TODAY())&"天後到期"))) | K17: 0
A18: 開發現迭代任務 | B18: 開發任務 | C18: T1-D4 | D18: Anritsu設備Agent實作 | E18: Anritsu設備Agent實作 | F18: Anritsu Agent程式碼 | G18: Patty | H18: 2026-09-15 | J18: =IF(I18<>"", IF(I18>DATEVALUE(H18),"🔴 逾期 "&(I18-DATEVALUE(H18))&"天", IF(DATEVALUE(H18)>I18,"🟢 提前 "&(DATEVALUE(H18)-I18)&"天","🟡 準時完成")), IF((DATEVALUE(H18)-TODAY())<=3,"🟡 接近截止（"&(DATEVALUE(H18)-TODAY())&"天）", IF(TODAY()>DATEVALUE(H18),"🔴 逾期 "&(TODAY()-DATEVALUE(H18))&"天（未完成）","🟢 " &(DATEVALUE(H18)-TODAY())&"天後到期"))) | K18: 0
A19: 開發現迭代任務 | B19: 開發任務 | C19: T1-D5 | D19: L3~L5串接整合 | E19: L3/L4/L5 Agent系統整合測試 | F19: 整合測試報告 | G19: Anderson | H19: 2026-09-20 | J19: =IF(I19<>"", IF(I19>DATEVALUE(H19),"🔴 逾期 "&(I19-DATEVALUE(H19))&"天", IF(DATEVALUE(H19)>I19,"🟢 提前 "&(DATEVALUE(H19)-I19)&"天","🟡 準時完成")), IF((DATEVALUE(H19)-TODAY())<=3,"🟡 接近截止（"&(DATEVALUE(H19)-TODAY())&"天）", IF(TODAY()>DATEVALUE(H19),"🔴 逾期 "&(TODAY()-DATEVALUE(H19))&"天（未完成）","🟢 " &(DATEVALUE(H19)-TODAY())&"天後到期"))) | K19: 0
A20: 系統整合測試
A21: 系統整合測試 | B21: 測試 | C21: T1-T1 | D21: 單元測試 | E21: 各模組單元測試 | F21: 單元測試報告 | G21: Anderson | H21: 2026-09-22 | J21: =IF(I21<>"", IF(I21>DATEVALUE(H21),"🔴 逾期 "&(I21-DATEVALUE(H21))&"天", IF(DATEVALUE(H21)>I21,"🟢 提前 "&(DATEVALUE(H21)-I21)&"天","🟡 準時完成")), IF((DATEVALUE(H21)-TODAY())<=3,"🟡 接近截止（"&(DATEVALUE(H21)-TODAY())&"天）", IF(TODAY()>DATEVALUE(H21),"🔴 逾期 "&(TODAY()-DATEVALUE(H21))&"天（未完成）","🟢 " &(DATEVALUE(H21)-TODAY())&"天後到期"))) | K21: 0
A22: 系統整合測試 | B22: 測試 | C22: T1-T2 | D22: 整合測試 | E22: 跨模組整合測試驗證 | F22: 整合測試報告 | G22: Patty | H22: 2026-09-28 | J22: =IF(I22<>"", IF(I22>DATEVALUE(H22),"🔴 逾期 "&(I22-DATEVALUE(H22))&"天", IF(DATEVALUE(H22)>I22,"🟢 提前 "&(DATEVALUE(H22)-I22)&"天","🟡 準時完成")), IF((DATEVALUE(H22)-TODAY())<=3,"🟡 接近截止（"&(DATEVALUE(H22)-TODAY())&"天）", IF(TODAY()>DATEVALUE(H22),"🔴 逾期 "&(TODAY()-DATEVALUE(H22))&"天（未完成）","🟢 " &(DATEVALUE(H22)-TODAY())&"天後到期"))) | K22: 0
A23: 系統整合測試 | B23: 測試 | C23: T1-T3 | D23: UAT使用者驗收測試 | E23: UAT測試與結果確認 | F23: UAT測試報告 | G23: Anderson | H23: 2026-10-05 | J23: =IF(I23<>"", IF(I23>DATEVALUE(H23),"🔴 逾期 "&(I23-DATEVALUE(H23))&"天", IF(DATEVALUE(H23)>I23,"🟢 提前 "&(DATEVALUE(H23)-I23)&"天","🟡 準時完成")), IF((DATEVALUE(H23)-TODAY())<=3,"🟡 接近截止（"&(DATEVALUE(H23)-TODAY())&"天）", IF(TODAY()>DATEVALUE(H23),"🔴 逾期 "&(TODAY()-DATEVALUE(H23))&"天（未完成）","🟢 " &(DATEVALUE(H23)-TODAY())&"天後到期"))) | K23: 0
A24: 驗收交付標準
A25: 驗收交付標準 | B25: 驗收 | C25: T1-V1 | D25: 功能驗收 | E25: 所有規劃功能符合需求規格 | F25: 驗收確認書 | G25: Patty | H25: 2026-10-10 | J25: =IF(I25<>"", IF(I25>DATEVALUE(H25),"🔴 逾期 "&(I25-DATEVALUE(H25))&"天", IF(DATEVALUE(H25)>I25,"🟢 提前 "&(DATEVALUE(H25)-I25)&"天","🟡 準時完成")), IF((DATEVALUE(H25)-TODAY())<=3,"🟡 接近截止（"&(DATEVALUE(H25)-TODAY())&"天）", IF(TODAY()>DATEVALUE(H25),"🔴 逾期 "&(TODAY()-DATEVALUE(H25))&"天（未完成）","🟢 " &(DATEVALUE(H25)-TODAY())&"天後到期"))) | K25: 0
A26: 驗收交付標準 | B26: 驗收 | C26: T1-V2 | D26: 效能驗收 | E26: 系統效能符合預定標準 | F26: 效能測試報告 | G26: Anderson | H26: 2026-10-12 | J26: =IF(I26<>"", IF(I26>DATEVALUE(H26),"🔴 逾期 "&(I26-DATEVALUE(H26))&"天", IF(DATEVALUE(H26)>I26,"🟢 提前 "&(DATEVALUE(H26)-I26)&"天","🟡 準時完成")), IF((DATEVALUE(H26)-TODAY())<=3,"🟡 接近截止（"&(DATEVALUE(H26)-TODAY())&"天）", IF(TODAY()>DATEVALUE(H26),"🔴 逾期 "&(TODAY()-DATEVALUE(H26))&"天（未完成）","🟢 " &(DATEVALUE(H26)-TODAY())&"天後到期"))) | K26: 0
A27: 文件化與知識傳承
A28: 文件化與知識傳承 | B28: 文件編寫 | C28: T1-Doc1 | D28: 設備操作SOP編寫 | E28: 設備操作標準程序手冊 | F28: 設備操作SOP文件 | G28: Patty | H28: 2026-10-15 | J28: =IF(I28<>"", IF(I28>DATEVALUE(H28),"🔴 逾期 "&(I28-DATEVALUE(H28))&"天", IF(DATEVALUE(H28)>I28,"🟢 提前 "&(DATEVALUE(H28)-I28)&"天","🟡 準時完成")), IF((DATEVALUE(H28)-TODAY())<=3,"🟡 接近截止（"&(DATEVALUE(H28)-TODAY())&"天）", IF(TODAY()>DATEVALUE(H28),"🔴 逾期 "&(TODAY()-DATEVALUE(H28))&"天（未完成）","🟢 " &(DATEVALUE(H28)-TODAY())&"天後到期"))) | K28: 0
A29: 文件化與知識傳承 | B29: 文件編寫 | C29: T1-Doc2 | D29: Agent使用手冊 | E29: 各層級Agent使用手冊編寫 | F29: Agent使用手冊 | G29: Anderson | H29: 2026-10-18 | J29: =IF(I29<>"", IF(I29>DATEVALUE(H29),"🔴 逾期 "&(I29-DATEVALUE(H29))&"天", IF(DATEVALUE(H29)>I29,"🟢 提前 "&(DATEVALUE(H29)-I29)&"天","🟡 準時完成")), IF((DATEVALUE(H29)-TODAY())<=3,"🟡 接近截止（"&(DATEVALUE(H29)-TODAY())&"天）", IF(TODAY()>DATEVALUE(H29),"🔴 逾期 "&(TODAY()-DATEVALUE(H29))&"天（未完成）","🟢 " &(DATEVALUE(H29)-TODAY())&"天後到期"))) | K29: 0
A30: 文件化與知識傳承 | B30: 知識庫建置 | C30: T1-Doc3 | D30: 經驗知識庫建置 | E30: Neo4j經驗知識庫建置與資料遷移 | F30: Neo4j知識庫 | G30: Anderson | H30: 2026-10-25 | J30: =IF(I30<>"", IF(I30>DATEVALUE(H30),"🔴 逾期 "&(I30-DATEVALUE(H30))&"天", IF(DATEVALUE(H30)>I30,"🟢 提前 "&(DATEVALUE(H30)-I30)&"天","🟡 準時完成")), IF((DATEVALUE(H30)-TODAY())<=3,"🟡 接近截止（"&(DATEVALUE(H30)-TODAY())&"天）", IF(TODAY()>DATEVALUE(H30),"🔴 逾期 "&(TODAY()-DATEVALUE(H30))&"天（未完成）","🟢 " &(DATEVALUE(H30)-TODAY())&"天後到期"))) | K30: 0

Sheet T2開發計劃
A1: T1開發計劃｜Anderson：KM優化與Sub2API建置管理
A2: 負責人：Anderson ｜ 計畫基準：2026-08-10 ｜ 本週：2026-W35（08/24～08/28） ｜ 依據：AI KM v2.6與既有驗證紀錄 | M2: ▸ 請填入實際檔案路徑或 SharePoint 連結 | N2: ▸ 本週的關鍵技術判斷？為什麼這樣決定？ | O2: ▸ 本週否決過AI的哪個建議？為什麼？
A3: 階段 | B3: 子階段 | C3: 任務編號 | D3: 任務名稱 | E3: 任務說明 | F3: 交付產出 | G3: 負責人 | H3: 預計完成日 | I3: 實際完成日 | J3: 開發狀態 | K3: 進度(%) | L3: 備註 | M3: 交付路徑 | N3: 關鍵判斷 | O3: 否決AI記錄
A4: KM優化｜本週規劃與基準
A5: KM優化 | B5: 規劃基準 | C5: T1-KM-01 | D5: v2.6範圍與責任校正 | E5: 確認Phase 1 MVP、Owner、前置依賴及12～16週排程；本週所有新增開發均歸屬KM優化。 | F5: v2.6基準與差異評估 | G5: Anderson | H5: 46245 | I5: 46245 | J5: =IF(I5<>"",IF(I5>H5,"逾期 "&(I5-H5)&"天",IF(H5>I5,"提前 "&(H5-I5)&"天","準時完成")),IF(TODAY()>H5,"逾期 "&(TODAY()-H5)&"天（未完成）",IF((H5-TODAY())<=3,"接近截止（"&(H5-TODAY())&"天）",(H5-TODAY())&"天後到期"))) | K5: 100 | L5: 本週完成；CSIT Web／DB Schema／Workflow及商業邏輯由Patty負責。 | M5: 01_AI_KM_Phase規劃_v2.6.xlsx；docs/km-modernization/06-v2.6-anderson-scope.md | N5: 以v2.6為唯一規劃基準，保留WP0/WP1歷史並以證據重新歸類。 | O5: 否決沿用舊Phase 0命名或缺證據宣稱完成。
A6: KM優化 | B6: WP0 | C6: T1-KM-02 | D6: WP0 FastAPI Contract正式化 | E6: 新增v1 health/version、統一error envelope與Trace ID，保留Portal、chat、search、report、ingest與A2A相容。 | F6: WP0程式、測試與部署證據 | G6: Anderson | H6: 46248 | I6: 46261 | J6: =IF(I6<>"",IF(I6>H6,"逾期 "&(I6-H6)&"天",IF(H6>I6,"提前 "&(H6-I6)&"天","準時完成")),IF(TODAY()>H6,"逾期 "&(TODAY()-H6)&"天（未完成）",IF((H6-TODAY())<=3,"接近截止（"&(H6-TODAY())&"天）",(H6-TODAY())&"天後到期"))) | K6: 100 | L6: WP0 Production Acceptance與Browser Evidence均PASS；WP0=100% Final Closed。PR #5 delivery attribution保留。 | M6: GitHub agent/wp01-production-rollout；WP0 evidence／CI | N6: 採additive contract與legacy compatibility，避免一次性破壞。 | O6: 否決直接移除或改名既有API。
A7: KM優化｜WP0／WP1可靠性與部署
A8: KM優化 | B8: WP1 | C8: T1-KM-03 | D8: WP1 Job可靠性與回退正式化 | E8: 完成Docker／Redis／Celery設定、queue分流、retry／trace／idempotency、pre-WP01備份及production rollback。 | F8: WP1程式、90 tests、shadow／production回退證據 | G8: Anderson | H8: 46255 | I8: 46261 | J8: =IF(I8<>"",IF(I8>H8,"逾期 "&(I8-H8)&"天",IF(H8>I8,"提前 "&(H8-I8)&"天","準時完成")),IF(TODAY()>H8,"逾期 "&(TODAY()-H8)&"天（未完成）",IF((H8-TODAY())<=3,"接近截止（"&(H8-TODAY())&"天）",(H8-TODAY())&"天後到期"))) | K8: 100 | L8: WP1=100% Final Closed；canonical integration與Production Acceptance已由主管接受。後續nginx activation屬新的production review，不改closure reporting。 | M8: docs/pre-wp01-deployment-record-20260811.md；GitHub agent/wp01-production-rollout | N8: 先備份及shadow回退，再切換真實系統；故障時先回退再修正。 | O8: 否決無checkpoint或未演練rollback就部署。
A9: KM優化 | B9: 維運工具 | C9: T1-KM-04 | D9: restart_kb生命週期安全重構 | E9: 拆分status／restart／deploy；加入env preflight、任務drain、WP0/WP1 Gate、candidate tag與失敗回退。 | F9: 安全腳本、8 tests、runbook與GitHub commit | G9: Anderson | H9: 46248 | I9: 46261 | J9: =IF(I9<>"",IF(I9>H9,"逾期 "&(I9-H9)&"天",IF(H9>I9,"提前 "&(H9-I9)&"天","準時完成")),IF(TODAY()>H9,"逾期 "&(TODAY()-H9)&"天（未完成）",IF((H9-TODAY())<=3,"接近截止（"&(H9-TODAY())&"天）",(H9-TODAY())&"天後到期"))) | K9: 100 | L9: restart_kb pinned deployment tooling與nginx remediation alignment完成；PR #27 activation review仍待主管核准，未執行production reload。 | M9: restart_kb.sh；docs/wp01-lifecycle-runbook.md；commit b33e3983 | N9: 無參數只讀；restart不碰資料服務；deploy須checkpoint與確認碼。 | O9: 否決把重建、重啟與部署混在同一個無確認流程。
A10: KM優化｜下週工作與前置條件
A11: KM優化 | B11: 下週驗收 | C11: T1-KM-05 | D11: WP0／WP1 PR Review與Merge Gate | E11: 補齊rollout PR、Review、CI、durable evidence、文件與回滾驗收，依證據關閉WP。 | F11: PR／CI／Review／Gate checklist | G11: Anderson | H11: 46255 | I11: 46261 | J11: =IF(I11<>"",IF(I11>H11,"逾期 "&(I11-H11)&"天",IF(H11>I11,"提前 "&(H11-I11)&"天","準時完成")),IF(TODAY()>H11,"逾期 "&(TODAY()-H11)&"天（未完成）",IF((H11-TODAY())<=3,"接近截止（"&(H11-TODAY())&"天）",(H11-TODAY())&"天後到期"))) | K11: 100 | L11: WP0/WP1 closure、governance與historical PR disposition已完成；PR #27為後續runtime activation review，保持Draft/Open。 | M11: 預計：GitHub PR與Actions evidence | N11: 把程式完成、測試通過、部署完成與正式驗收分開管理。 | O11: 不以本機或production smoke取代PR Review。
A12: KM優化 | B12: 下週驗收 | C12: T1-KM-06 | D12: restart／deploy shadow演練 | E12: 以隔離stack驗證安全restart、candidate failure、前端恢復與application rollback，不觸碰正式資料。 | F12: shadow演練紀錄與RTO | G12: Anderson | H12: 46255 | I12: 46255 | J12: =IF(I12<>"",IF(I12>H12,"逾期 "&(I12-H12)&"天",IF(H12>I12,"提前 "&(H12-I12)&"天","準時完成")),IF(TODAY()>H12,"逾期 "&(TODAY()-H12)&"天（未完成）",IF((H12-TODAY())<=3,"接近截止（"&(H12-TODAY())&"天）",(H12-TODAY())&"天後到期"))) | K12: 100 | L12: shadow restart／candidate failure／application rollback演練已通過；正式維護窗口仍待核准。 | M12: 預計：$HOME/kb-pre-wp01-drills／runbook evidence | N12: 失敗注入與回退必須走和正式環境相同的script路徑。 | O12: 否決直接在production測試--deploy。
A13: KM優化 | B13: 下週前置 | C13: T1-KM-07 | D13: CSIT API Contract與Fake Adapter盤點 | E13: 整理Request／Response、權限、狀態與錯誤碼；依核准Contract規劃AI KM Client／Fake Adapter。 | F13: Contract需求清單與Adapter測試案例 | G13: Anderson | H13: 46267 | J13: =IF(I13<>"",IF(I13>H13,"逾期 "&(I13-H13)&"天",IF(H13>I13,"提前 "&(H13-I13)&"天","準時完成")),IF(TODAY()>H13,"逾期 "&(TODAY()-H13)&"天（未完成）",IF((H13-TODAY())<=3,"接近截止（"&(H13-TODAY())&"天）",(H13-TODAY())&"天後到期"))) | K13: 0 | L13: 下週開始前置盤點；Patty提供正式CSIT Contract。 | M13: 預計：docs/km-modernization／contract evidence | N13: 跨系統以Contract隔離，Anderson不修改CSIT內部程式。 | O13: 否決AI KM直連CSIT DB或自行推測Schema。
A14: KM優化｜Phase 1後續排程
A15: KM優化 | B15: Phase 1 | C15: T1-KM-08 | D15: Excel Report Parser／Schema Validation | E15: 依正式欄位Schema解析與拒絕錯誤資料，錯誤需可追蹤。 | F15: Parser／Validator與Unit Test | G15: Anderson | H15: 46324 | J15: =IF(I15<>"",IF(I15>H15,"逾期 "&(I15-H15)&"天",IF(H15>I15,"提前 "&(H15-I15)&"天","準時完成")),IF(TODAY()>H15,"逾期 "&(TODAY()-H15)&"天（未完成）",IF((H15-TODAY())<=3,"接近截止（"&(H15-TODAY())&"天）",(H15-TODAY())&"天後到期"))) | K15: 0 | L15: 依v2.6排程；前置為正式報告欄位Schema。 | M15: 預計：parser／validation modules | N15: 固定程式處理型別與規則，不讓LLM補造正式欄位。 | O15: 不在Schema未核准前承諾完成。
A16: KM優化 | B16: Phase 1 | C16: T1-KM-09 | D16: MarkItDown／Chunk／Embedding正式化 | E16: 整理既有POC、禁止整份文件單一chunk、保留來源並支援重跑。 | F16: RAG pipeline與Unit Test | G16: Anderson | H16: 46335 | J16: =IF(I16<>"",IF(I16>H16,"逾期 "&(I16-H16)&"天",IF(H16>I16,"提前 "&(H16-I16)&"天","準時完成")),IF(TODAY()>H16,"逾期 "&(TODAY()-H16)&"天（未完成）",IF((H16-TODAY())<=3,"接近截止（"&(H16-TODAY())&"天）",(H16-TODAY())&"天後到期"))) | K16: 0 | L16: 依v2.6排程；沿用現有POC後正式化。 | M16: 預計：RAG／chunk evidence | N16: 先沿用可用POC，再以最低正式規格收斂。 | O16: 否決Phase 1同時重做完整Document Intelligence。
A17: KM優化 | B17: Phase 1 | C17: T1-KM-10 | D17: Qdrant基本向量搜尋正式化 | E17: 依Payload／Chunk／Filter／Version／ACL最低規格完成upsert、search與重跑去重。 | F17: Qdrant collection／search tests | G17: Anderson | H17: 46344 | J17: =IF(I17<>"",IF(I17>H17,"逾期 "&(I17-H17)&"天",IF(H17>I17,"提前 "&(H17-I17)&"天","準時完成")),IF(TODAY()>H17,"逾期 "&(TODAY()-H17)&"天（未完成）",IF((H17-TODAY())<=3,"接近截止（"&(H17-TODAY())&"天）",(H17-TODAY())&"天後到期"))) | K17: 0 | L17: 依v2.6排程；前置為最低Knowledge Schema。 | M17: 預計：Qdrant evidence | N17: Draft或無權限資料不可被正式查詢。 | O17: 不先改collection再補Schema。
A18: KM優化 | B18: Phase 1 | C18: T1-KM-11 | D18: Neo4j基本GraphRAG正式化 | E18: 依最低Ontology、Node、Relationship與Source規則實作MERGE及查詢。 | F18: GraphRAG／Cypher／重跑測試 | G18: Anderson | H18: 46353 | J18: =IF(I18<>"",IF(I18>H18,"逾期 "&(I18-H18)&"天",IF(H18>I18,"提前 "&(H18-I18)&"天","準時完成")),IF(TODAY()>H18,"逾期 "&(TODAY()-H18)&"天（未完成）",IF((H18-TODAY())<=3,"接近截止（"&(H18-TODAY())&"天）",(H18-TODAY())&"天後到期"))) | K18: 0 | L18: 依v2.6排程；前置為Ontology與Source規格。 | M18: 預計：Neo4j evidence | N18: 實體關係固定且可追溯，不把整篇文章當知識節點。 | O18: 不在Ontology未定義前自由產生Graph schema。
A19: KM優化 | B19: Phase 1 | C19: T1-KM-12 | D19: TimescaleDB／Portal／Phase 1總驗收 | E19: 12/8完成時序基礎、12/31完成Portal，2027/1/14完成Unit／Integration／Acceptance／Golden Test。 | F19: TimescaleDB、Portal與Phase 1驗收證據 | G19: Anderson | H19: 46401 | J19: =IF(I19<>"",IF(I19>H19,"逾期 "&(I19-H19)&"天",IF(H19>I19,"提前 "&(H19-I19)&"天","準時完成")),IF(TODAY()>H19,"逾期 "&(TODAY()-H19)&"天（未完成）",IF((H19-TODAY())<=3,"接近截止（"&(H19-TODAY())&"天）",(H19-TODAY())&"天後到期"))) | K19: 0 | L19: 里程碑：TimescaleDB 12/8；Portal 12/31；總驗收2027/1/14。 | M19: 預計：Phase 1 gate evidence | N19: 依前置依賴分段交付，Phase 1整體12～16週。 | O19: 不把尚未開始的後續模組填入虛構進度。
A20: Sub2API｜既有建置成果
A21: Sub2API | B21: 既有建置 | C21: T1-S2A-01 | D21: 隔離部署與模型路由 | E21: 完成Sub2API隔離部署、Test_Local群組、Ollama模型同步及外部路由。 | F21: 部署與模型清單 | G21: Anderson | H21: 46237 | I21: 46237 | J21: =IF(I21<>"",IF(I21>H21,"逾期 "&(I21-H21)&"天",IF(H21>I21,"提前 "&(H21-I21)&"天","準時完成")),IF(TODAY()>H21,"逾期 "&(TODAY()-H21)&"天（未完成）",IF((H21-TODAY())<=3,"接近截止（"&(H21-TODAY())&"天）",(H21-TODAY())&"天後到期"))) | K21: 100 | L21: 既有完成，非本週新增開發。 | M21: Sub2API部署紀錄；Test_Local／Ollama | N21: 以群組、渠道與Key分離使用情境。 | O21: 否決硬編碼正式帳密或Token。
A22: Sub2API | B22: 既有建置 | C22: T1-S2A-02 | D22: OpenAI渠道與監控情境 | E22: 完成openAI_wifisit01→WifiSit01_DA40渠道，建立gpt-5.4／gpt-5.4-mini監控情境。 | F22: 渠道設定與健康監控紀錄 | G22: Anderson | H22: 46237 | I22: 46237 | J22: =IF(I22<>"",IF(I22>H22,"逾期 "&(I22-H22)&"天",IF(H22>I22,"提前 "&(H22-I22)&"天","準時完成")),IF(TODAY()>H22,"逾期 "&(TODAY()-H22)&"天（未完成）",IF((H22-TODAY())<=3,"接近截止（"&(H22-TODAY())&"天）",(H22-TODAY())&"天後到期"))) | K22: 100 | L22: 既有完成，需持續觀察渠道健康與成本。 | M22: Sub2API channel／monitor設定 | N22: 渠道可用性與帳務可稽核性分開驗收。 | O22: 不以單次請求成功代表正式SLA。
A23: Sub2API | B23: 既有建置 | C23: T1-S2A-03 | D23: 測試訂閱管理情境 | E23: 建立30日零元測試訂閱與有效期情境，確認使用者訂閱狀態。 | F23: 訂閱情境與驗證紀錄 | G23: Anderson | H23: 46237 | I23: 46237 | J23: =IF(I23<>"",IF(I23>H23,"逾期 "&(I23-H23)&"天",IF(H23>I23,"提前 "&(H23-I23)&"天","準時完成")),IF(TODAY()>H23,"逾期 "&(TODAY()-H23)&"天（未完成）",IF((H23-TODAY())<=3,"接近截止（"&(H23-TODAY())&"天）",(H23-TODAY())&"天後到期"))) | K23: 100 | L23: 既有完成；零元測試不等於正式商業付款流程。 | M23: Sub2API subscription設定 | N23: 技術訂閱與商業計費必須分開宣稱。 | O23: 否決把測試訂閱描述成正式商業訂閱。
A24: Sub2API｜近期管理計畫
A25: Sub2API | B25: 近期管理 | C25: T1-S2A-04 | D25: 用量歸屬、報表與告警 | E25: 釐清usage_logs.subscription_id關聯，建立群組／渠道／使用者用量核對與額度／到期告警。 | F25: 用量報表與告警驗收案例 | G25: Anderson | H25: 46255 | J25: =IF(I25<>"",IF(I25>H25,"逾期 "&(I25-H25)&"天",IF(H25>I25,"提前 "&(H25-I25)&"天","準時完成")),IF(TODAY()>H25,"逾期 "&(TODAY()-H25)&"天（未完成）",IF((H25-TODAY())<=3,"接近截止（"&(H25-TODAY())&"天）",(H25-TODAY())&"天後到期"))) | K25: 10 | L25: 已完成缺口分析；下週進入資料關聯與驗收設計。 | M25: 預計：usage／subscription evidence | N25: 用資料關聯與可重現測試驗證歸屬。 | O25: 不在缺少用量證據時啟用正式扣款。
A26: Sub2API | B26: 近期管理 | C26: T1-S2A-05 | D26: TLS／SSRF／Key輪替與群組隔離 | E26: 完成HTTPS、Ollama端點allowlist、最小權限、Key rotation及跨群組隔離測試。 | F26: 安全設定與隔離測試報告 | G26: Anderson | H26: 46262 | J26: =IF(I26<>"",IF(I26>H26,"逾期 "&(I26-H26)&"天",IF(H26>I26,"提前 "&(H26-I26)&"天","準時完成")),IF(TODAY()>H26,"逾期 "&(TODAY()-H26)&"天（未完成）",IF((H26-TODAY())<=3,"接近截止（"&(H26-TODAY())&"天）",(H26-TODAY())&"天後到期"))) | K26: 10 | L26: 已完成風險評估，待正式執行。 | M26: 預計：security hardening evidence | N26: 安全控制由可配置規則與部署邊界落實。 | O26: 否決在TLS未完成或SSRF allowlist關閉時正式開放。
A27: Sub2API｜正式化與維運排程
A28: Sub2API | B28: 正式化 | C28: T1-S2A-06 | D28: 方案、模型價格與Quota設計 | E28: 依真實用量建立方案矩陣、模型價格、群組配額與成本基線。 | F28: 方案／價格／Quota矩陣 | G28: Anderson | H28: 46269 | J28: =IF(I28<>"",IF(I28>H28,"逾期 "&(I28-H28)&"天",IF(H28>I28,"提前 "&(H28-I28)&"天","準時完成")),IF(TODAY()>H28,"逾期 "&(TODAY()-H28)&"天（未完成）",IF((H28-TODAY())<=3,"接近截止（"&(H28-TODAY())&"天）",(H28-TODAY())&"天後到期"))) | K28: 5 | L28: 已完成方向評估，待真實用量資料。 | M28: 預計：commercial plan | N28: 先有成本基線，再決定方案與付款整合。 | O28: 不在成本未知時承諾固定價格。
A29: Sub2API | B29: 正式化 | C29: T1-S2A-07 | D29: SLA監控、備份還原與事件Runbook | E29: 建立告警門檻、備份／還原演練、渠道異常與訂閱事件處理流程。 | F29: SLA dashboard與維運Runbook | G29: Anderson | H29: 46276 | J29: =IF(I29<>"",IF(I29>H29,"逾期 "&(I29-H29)&"天",IF(H29>I29,"提前 "&(H29-I29)&"天","準時完成")),IF(TODAY()>H29,"逾期 "&(TODAY()-H29)&"天（未完成）",IF((H29-TODAY())<=3,"接近截止（"&(H29-TODAY())&"天）",(H29-TODAY())&"天後到期"))) | K29: 5 | L29: 已完成範圍評估，尚未實作。 | M29: 預計：operations runbook | N29: 先建立可觀測性與回復能力，再擴大使用者。 | O29: 不在無備份與事件責任時全面開放。
A30: Sub2API | B30: 正式化 | C30: T1-S2A-08 | D30: 正式驗收與管理交接 | E30: 完成權限、成本、用量、SLA、備份與安全Gate後，建立月度檢查及管理責任。 | F30: 驗收清單與管理交接文件 | G30: Anderson | H30: 46295 | J30: =IF(I30<>"",IF(I30>H30,"逾期 "&(I30-H30)&"天",IF(H30>I30,"提前 "&(H30-I30)&"天","準時完成")),IF(TODAY()>H30,"逾期 "&(TODAY()-H30)&"天（未完成）",IF((H30-TODAY())<=3,"接近截止（"&(H30-TODAY())&"天）",(H30-TODAY())&"天後到期"))) | K30: 0 | L30: 排程已訂；依前述安全與用量Gate完成後啟動。 | M30: 預計：acceptance／handover evidence | N30: 正式開放以Gate證據決定，不以功能存在決定。 | O30: 不在責任、成本與安全未定義前正式上線。

Sheet T3開發計劃
A1: T3開發計劃｜CSIT System驗證申請系統
A2: 負責人：Patty ｜ 建立日期：2026-07-31 | M2: ▸ 請填入實際檔案路徑或 SharePoint 連結 | N2: ▸ 本週的關鍵技術判斷？為什麼這樣決定？ | O2: ▸ 本週否決過AI的哪個建議？為什麼？
A3: 階段 | B3: 子階段 | C3: 任務編號 | D3: 任務名稱 | E3: 任務說明 | F3: 交付產出 | G3: 負責人 | H3: 預計完成日 | I3: 實際完成日 | J3: 開發狀態 | K3: 進度(%) | L3: 備註 | M3: 交付路徑 | N3: 關鍵判斷 | O3: 否決AI記錄
A4: 系統架構設計
A5: 系統架構設計 | B5: 架構規劃 | C5: T3-A1 | D5: 系統架構設計 | E5: CSIT驗證申請系統整體架構設計 | F5: 系統架構文件 | G5: Patty | H5: 2026-08-25 | J5: =IF(I5<>"", IF(I5>DATEVALUE(H5),"🔴 逾期 "&(I5-DATEVALUE(H5))&"天", IF(DATEVALUE(H5)>I5,"🟢 提前 "&(DATEVALUE(H5)-I5)&"天","🟡 準時完成")), IF((DATEVALUE(H5)-TODAY())<=3,"🟡 接近截止（"&(DATEVALUE(H5)-TODAY())&"天）", IF(TODAY()>DATEVALUE(H5),"🔴 逾期 "&(TODAY()-DATEVALUE(H5))&"天（未完成）","🟢 " &(DATEVALUE(H5)-TODAY())&"天後到期"))) | K5: 0
A6: 系統架構設計 | B6: 資料庫設計 | C6: T3-A2 | D6: 資料庫設計 | E6: 申請資料與流程資料庫設計 | F6: 資料庫規格文件 | G6: Patty | H6: 2026-09-01 | J6: =IF(I6<>"", IF(I6>DATEVALUE(H6),"🔴 逾期 "&(I6-DATEVALUE(H6))&"天", IF(DATEVALUE(H6)>I6,"🟢 提前 "&(DATEVALUE(H6)-I6)&"天","🟡 準時完成")), IF((DATEVALUE(H6)-TODAY())<=3,"🟡 接近截止（"&(DATEVALUE(H6)-TODAY())&"天）", IF(TODAY()>DATEVALUE(H6),"🔴 逾期 "&(TODAY()-DATEVALUE(H6))&"天（未完成）","🟢 " &(DATEVALUE(H6)-TODAY())&"天後到期"))) | K6: 0
A7: 系統流程設計
A8: 系統流程設計 | B8: 流程設計 | C8: T3-B1 | D8: 申請流程設計 | E8: 驗證申請線上流程設計 | F8: 申請流程圖 | G8: Patty | H8: 2026-09-05 | J8: =IF(I8<>"", IF(I8>DATEVALUE(H8),"🔴 逾期 "&(I8-DATEVALUE(H8))&"天", IF(DATEVALUE(H8)>I8,"🟢 提前 "&(DATEVALUE(H8)-I8)&"天","🟡 準時完成")), IF((DATEVALUE(H8)-TODAY())<=3,"🟡 接近截止（"&(DATEVALUE(H8)-TODAY())&"天）", IF(TODAY()>DATEVALUE(H8),"🔴 逾期 "&(TODAY()-DATEVALUE(H8))&"天（未完成）","🟢 " &(DATEVALUE(H8)-TODAY())&"天後到期"))) | K8: 0
A9: 系統流程設計 | B9: 流程設計 | C9: T3-B2 | D9: 審核流程設計 | E9: 審核單位審核流程設計 | F9: 審核流程圖 | G9: Patty | H9: 2026-09-08 | J9: =IF(I9<>"", IF(I9>DATEVALUE(H9),"🔴 逾期 "&(I9-DATEVALUE(H9))&"天", IF(DATEVALUE(H9)>I9,"🟢 提前 "&(DATEVALUE(H9)-I9)&"天","🟡 準時完成")), IF((DATEVALUE(H9)-TODAY())<=3,"🟡 接近截止（"&(DATEVALUE(H9)-TODAY())&"天）", IF(TODAY()>DATEVALUE(H9),"🔴 逾期 "&(TODAY()-DATEVALUE(H9))&"天（未完成）","🟢 " &(DATEVALUE(H9)-TODAY())&"天後到期"))) | K9: 0
A10: 知識工程與需求訪談
A11: 知識工程與需求訪談 | B11: 需求訪談 | C11: T3-K1 | D11: 需求訪談 | E11: 使用單位、審核單位需求訪談 | F11: 需求訪談紀錄 | G11: Patty | H11: 2026-08-18 | J11: =IF(I11<>"", IF(I11>DATEVALUE(H11),"🔴 逾期 "&(I11-DATEVALUE(H11))&"天", IF(DATEVALUE(H11)>I11,"🟢 提前 "&(DATEVALUE(H11)-I11)&"天","🟡 準時完成")), IF((DATEVALUE(H11)-TODAY())<=3,"🟡 接近截止（"&(DATEVALUE(H11)-TODAY())&"天）", IF(TODAY()>DATEVALUE(H11),"🔴 逾期 "&(TODAY()-DATEVALUE(H11))&"天（未完成）","🟢 " &(DATEVALUE(H11)-TODAY())&"天後到期"))) | K11: 0
A12: 知識工程與需求訪談 | B12: 瓶頸分析 | C12: T3-K2 | D12: 現有申請流程收集與瓶頸分析 | E12: 收集並分析現有申請流程痛點 | F12: 瓶頸分析報告 | G12: Patty | H12: 2026-08-22 | J12: =IF(I12<>"", IF(I12>DATEVALUE(H12),"🔴 逾期 "&(I12-DATEVALUE(H12))&"天", IF(DATEVALUE(H12)>I12,"🟢 提前 "&(DATEVALUE(H12)-I12)&"天","🟡 準時完成")), IF((DATEVALUE(H12)-TODAY())<=3,"🟡 接近截止（"&(DATEVALUE(H12)-TODAY())&"天）", IF(TODAY()>DATEVALUE(H12),"🔴 逾期 "&(TODAY()-DATEVALUE(H12))&"天（未完成）","🟢 " &(DATEVALUE(H12)-TODAY())&"天後到期"))) | K12: 0
A13: 知識工程與需求訪談 | B13: 需求訪談 | C13: T3-K3 | D13: 表單需求訪談 | E13: 各類申請表單需求訪談與彙整 | F13: 表單需求文件 | G13: Patty | H13: 2026-08-28 | J13: =IF(I13<>"", IF(I13>DATEVALUE(H13),"🔴 逾期 "&(I13-DATEVALUE(H13))&"天", IF(DATEVALUE(H13)>I13,"🟢 提前 "&(DATEVALUE(H13)-I13)&"天","🟡 準時完成")), IF((DATEVALUE(H13)-TODAY())<=3,"🟡 接近截止（"&(DATEVALUE(H13)-TODAY())&"天）", IF(TODAY()>DATEVALUE(H13),"🔴 逾期 "&(TODAY()-DATEVALUE(H13))&"天（未完成）","🟢 " &(DATEVALUE(H13)-TODAY())&"天後到期"))) | K13: 0
A14: 開發現迭代任務
A15: 開發現迭代任務 | B15: 開發任務 | C15: T3-D1 | D15: 系統開發 | E15: CSIT驗證申請系統功能開發 | F15: 系統程式碼 | G15: Patty | H15: 2026-09-20 | J15: =IF(I15<>"", IF(I15>DATEVALUE(H15),"🔴 逾期 "&(I15-DATEVALUE(H15))&"天", IF(DATEVALUE(H15)>I15,"🟢 提前 "&(DATEVALUE(H15)-I15)&"天","🟡 準時完成")), IF((DATEVALUE(H15)-TODAY())<=3,"🟡 接近截止（"&(DATEVALUE(H15)-TODAY())&"天）", IF(TODAY()>DATEVALUE(H15),"🔴 逾期 "&(TODAY()-DATEVALUE(H15))&"天（未完成）","🟢 " &(DATEVALUE(H15)-TODAY())&"天後到期"))) | K15: 0
A16: 開發現迭代任務 | B16: 開發任務 | C16: T3-D2 | D16: 單元測試 | E16: 各功能模組單元測試 | F16: 單元測試報告 | G16: Patty | H16: 2026-09-25 | J16: =IF(I16<>"", IF(I16>DATEVALUE(H16),"🔴 逾期 "&(I16-DATEVALUE(H16))&"天", IF(DATEVALUE(H16)>I16,"🟢 提前 "&(DATEVALUE(H16)-I16)&"天","🟡 準時完成")), IF((DATEVALUE(H16)-TODAY())<=3,"🟡 接近截止（"&(DATEVALUE(H16)-TODAY())&"天）", IF(TODAY()>DATEVALUE(H16),"🔴 逾期 "&(TODAY()-DATEVALUE(H16))&"天（未完成）","🟢 " &(DATEVALUE(H16)-TODAY())&"天後到期"))) | K16: 0
A17: 開發現迭代任務 | B17: 開發任務 | C17: T3-D3 | D17: 整合測試 | E17: 跨模組整合測試 | F17: 整合測試報告 | G17: Patty | H17: 2026-10-02 | J17: =IF(I17<>"", IF(I17>DATEVALUE(H17),"🔴 逾期 "&(I17-DATEVALUE(H17))&"天", IF(DATEVALUE(H17)>I17,"🟢 提前 "&(DATEVALUE(H17)-I17)&"天","🟡 準時完成")), IF((DATEVALUE(H17)-TODAY())<=3,"🟡 接近截止（"&(DATEVALUE(H17)-TODAY())&"天）", IF(TODAY()>DATEVALUE(H17),"🔴 逾期 "&(TODAY()-DATEVALUE(H17))&"天（未完成）","🟢 " &(DATEVALUE(H17)-TODAY())&"天後到期"))) | K17: 0
A18: 系統整合測試
A19: 系統整合測試 | B19: 測試 | C19: T3-T1 | D19: UAT測試 | E19: 使用者驗收測試 | F19: UAT測試報告 | G19: Patty | H19: 2026-10-08 | J19: =IF(I19<>"", IF(I19>DATEVALUE(H19),"🔴 逾期 "&(I19-DATEVALUE(H19))&"天", IF(DATEVALUE(H19)>I19,"🟢 提前 "&(DATEVALUE(H19)-I19)&"天","🟡 準時完成")), IF((DATEVALUE(H19)-TODAY())<=3,"🟡 接近截止（"&(DATEVALUE(H19)-TODAY())&"天）", IF(TODAY()>DATEVALUE(H19),"🔴 逾期 "&(TODAY()-DATEVALUE(H19))&"天（未完成）","🟢 " &(DATEVALUE(H19)-TODAY())&"天後到期"))) | K19: 0
A20: 驗收交付標準
A21: 驗收交付標準 | B21: 驗收 | C21: T3-V1 | D21: 功能驗收 | E21: 系統功能驗收確認 | F21: 驗收確認書 | G21: Patty | H21: 2026-10-15 | J21: =IF(I21<>"", IF(I21>DATEVALUE(H21),"🔴 逾期 "&(I21-DATEVALUE(H21))&"天", IF(DATEVALUE(H21)>I21,"🟢 提前 "&(DATEVALUE(H21)-I21)&"天","🟡 準時完成")), IF((DATEVALUE(H21)-TODAY())<=3,"🟡 接近截止（"&(DATEVALUE(H21)-TODAY())&"天）", IF(TODAY()>DATEVALUE(H21),"🔴 逾期 "&(TODAY()-DATEVALUE(H21))&"天（未完成）","🟢 " &(DATEVALUE(H21)-TODAY())&"天後到期"))) | K21: 0
A22: 文件化與知識傳承
A23: 文件化與知識傳承 | B23: 文件編寫 | C23: T3-Doc1 | D23: 操作手冊 | E23: 使用者操作手冊編寫 | F23: 操作手冊文件 | G23: Patty | H23: 2026-10-18 | J23: =IF(I23<>"", IF(I23>DATEVALUE(H23),"🔴 逾期 "&(I23-DATEVALUE(H23))&"天", IF(DATEVALUE(H23)>I23,"🟢 提前 "&(DATEVALUE(H23)-I23)&"天","🟡 準時完成")), IF((DATEVALUE(H23)-TODAY())<=3,"🟡 接近截止（"&(DATEVALUE(H23)-TODAY())&"天）", IF(TODAY()>DATEVALUE(H23),"🔴 逾期 "&(TODAY()-DATEVALUE(H23))&"天（未完成）","🟢 " &(DATEVALUE(H23)-TODAY())&"天後到期"))) | K23: 0
A24: 文件化與知識傳承 | B24: 文件編寫 | C24: T3-Doc2 | D24: 管理者SOP | E24: 系統管理者標準程序 | F24: 管理者SOP文件 | G24: Patty | H24: 2026-10-22 | J24: =IF(I24<>"", IF(I24>DATEVALUE(H24),"🔴 逾期 "&(I24-DATEVALUE(H24))&"天", IF(DATEVALUE(H24)>I24,"🟢 提前 "&(DATEVALUE(H24)-I24)&"天","🟡 準時完成")), IF((DATEVALUE(H24)-TODAY())<=3,"🟡 接近截止（"&(DATEVALUE(H24)-TODAY())&"天）", IF(TODAY()>DATEVALUE(H24),"🔴 逾期 "&(TODAY()-DATEVALUE(H24))&"天（未完成）","🟢 " &(DATEVALUE(H24)-TODAY())&"天後到期"))) | K24: 0

Sheet T4開發計劃
A1: T4開發計劃｜設備預約系統
A2: 負責人：Patty ｜ 建立日期：2026-07-31 | M2: ▸ 請填入實際檔案路徑或 SharePoint 連結 | N2: ▸ 本週的關鍵技術判斷？為什麼這樣決定？ | O2: ▸ 本週否決過AI的哪個建議？為什麼？
A3: 階段 | B3: 子階段 | C3: 任務編號 | D3: 任務名稱 | E3: 任務說明 | F3: 交付產出 | G3: 負責人 | H3: 預計完成日 | I3: 實際完成日 | J3: 開發狀態 | K3: 進度(%) | L3: 備註 | M3: 交付路徑 | N3: 關鍵判斷 | O3: 否決AI記錄
A4: 系統架構設計
A5: 系統架構設計 | B5: 架構規劃 | C5: T4-A1 | D5: 系統架構設計 | E5: 設備預約系統整體架構設計 | F5: 系統架構文件 | G5: Patty | H5: 2026-08-25 | J5: =IF(I5<>"", IF(I5>DATEVALUE(H5),"🔴 逾期 "&(I5-DATEVALUE(H5))&"天", IF(DATEVALUE(H5)>I5,"🟢 提前 "&(DATEVALUE(H5)-I5)&"天","🟡 準時完成")), IF((DATEVALUE(H5)-TODAY())<=3,"🟡 接近截止（"&(DATEVALUE(H5)-TODAY())&"天）", IF(TODAY()>DATEVALUE(H5),"🔴 逾期 "&(TODAY()-DATEVALUE(H5))&"天（未完成）","🟢 " &(DATEVALUE(H5)-TODAY())&"天後到期"))) | K5: 0
A6: 系統流程設計
A7: 系統流程設計 | B7: 流程設計 | C7: T4-B1 | D7: 預約流程設計 | E7: 設備預約取消與排程流程設計 | F7: 預約流程圖 | G7: Patty | H7: 2026-09-01 | J7: =IF(I7<>"", IF(I7>DATEVALUE(H7),"🔴 逾期 "&(I7-DATEVALUE(H7))&"天", IF(DATEVALUE(H7)>I7,"🟢 提前 "&(DATEVALUE(H7)-I7)&"天","🟡 準時完成")), IF((DATEVALUE(H7)-TODAY())<=3,"🟡 接近截止（"&(DATEVALUE(H7)-TODAY())&"天）", IF(TODAY()>DATEVALUE(H7),"🔴 逾期 "&(TODAY()-DATEVALUE(H7))&"天（未完成）","🟢 " &(DATEVALUE(H7)-TODAY())&"天後到期"))) | K7: 0
A8: 知識工程與需求訪談
A9: 知識工程與需求訪談 | B9: 需求訪談 | C9: T4-K1 | D9: 使用者訪談 | E9: 工程師、管理者需求訪談 | F9: 訪談紀錄 | G9: Patty | H9: 2026-08-18 | J9: =IF(I9<>"", IF(I9>DATEVALUE(H9),"🔴 逾期 "&(I9-DATEVALUE(H9))&"天", IF(DATEVALUE(H9)>I9,"🟢 提前 "&(DATEVALUE(H9)-I9)&"天","🟡 準時完成")), IF((DATEVALUE(H9)-TODAY())<=3,"🟡 接近截止（"&(DATEVALUE(H9)-TODAY())&"天）", IF(TODAY()>DATEVALUE(H9),"🔴 逾期 "&(TODAY()-DATEVALUE(H9))&"天（未完成）","🟢 " &(DATEVALUE(H9)-TODAY())&"天後到期"))) | K9: 0
A10: 知識工程與需求訪談 | B10: 問題收集 | C10: T4-K2 | D10: 現有問題收集 | E10: 現有預約問題與痛點收集 | F10: 問題分析報告 | G10: Patty | H10: 2026-08-22 | J10: =IF(I10<>"", IF(I10>DATEVALUE(H10),"🔴 逾期 "&(I10-DATEVALUE(H10))&"天", IF(DATEVALUE(H10)>I10,"🟢 提前 "&(DATEVALUE(H10)-I10)&"天","🟡 準時完成")), IF((DATEVALUE(H10)-TODAY())<=3,"🟡 接近截止（"&(DATEVALUE(H10)-TODAY())&"天）", IF(TODAY()>DATEVALUE(H10),"🔴 逾期 "&(TODAY()-DATEVALUE(H10))&"天（未完成）","🟢 " &(DATEVALUE(H10)-TODAY())&"天後到期"))) | K10: 0
A11: 開發現迭代任務
A12: 開發現迭代任務 | B12: 開發任務 | C12: T4-D1 | D12: 系統開發 | E12: 設備預約系統功能開發 | F12: 系統程式碼 | G12: Patty | H12: 2026-09-15 | J12: =IF(I12<>"", IF(I12>DATEVALUE(H12),"🔴 逾期 "&(I12-DATEVALUE(H12))&"天", IF(DATEVALUE(H12)>I12,"🟢 提前 "&(DATEVALUE(H12)-I12)&"天","🟡 準時完成")), IF((DATEVALUE(H12)-TODAY())<=3,"🟡 接近截止（"&(DATEVALUE(H12)-TODAY())&"天）", IF(TODAY()>DATEVALUE(H12),"🔴 逾期 "&(TODAY()-DATEVALUE(H12))&"天（未完成）","🟢 " &(DATEVALUE(H12)-TODAY())&"天後到期"))) | K12: 0
A13: 開發現迭代任務 | B13: 開發任務 | C13: T4-D2 | D13: 測試驗證 | E13: 系統測試與驗證 | F13: 測試報告 | G13: Patty | H13: 2026-09-22 | J13: =IF(I13<>"", IF(I13>DATEVALUE(H13),"🔴 逾期 "&(I13-DATEVALUE(H13))&"天", IF(DATEVALUE(H13)>I13,"🟢 提前 "&(DATEVALUE(H13)-I13)&"天","🟡 準時完成")), IF((DATEVALUE(H13)-TODAY())<=3,"🟡 接近截止（"&(DATEVALUE(H13)-TODAY())&"天）", IF(TODAY()>DATEVALUE(H13),"🔴 逾期 "&(TODAY()-DATEVALUE(H13))&"天（未完成）","🟢 " &(DATEVALUE(H13)-TODAY())&"天後到期"))) | K13: 0
A14: 系統整合測試
A15: 系統整合測試 | B15: 測試 | C15: T4-T1 | D15: UAT測試 | E15: 使用者驗收測試 | F15: UAT測試報告 | G15: Patty | H15: 2026-09-28 | J15: =IF(I15<>"", IF(I15>DATEVALUE(H15),"🔴 逾期 "&(I15-DATEVALUE(H15))&"天", IF(DATEVALUE(H15)>I15,"🟢 提前 "&(DATEVALUE(H15)-I15)&"天","🟡 準時完成")), IF((DATEVALUE(H15)-TODAY())<=3,"🟡 接近截止（"&(DATEVALUE(H15)-TODAY())&"天）", IF(TODAY()>DATEVALUE(H15),"🔴 逾期 "&(TODAY()-DATEVALUE(H15))&"天（未完成）","🟢 " &(DATEVALUE(H15)-TODAY())&"天後到期"))) | K15: 0
A16: 驗收交付標準
A17: 驗收交付標準 | B17: 驗收 | C17: T4-V1 | D17: 功能驗收 | E17: 系統功能驗收確認 | F17: 驗收確認書 | G17: Patty | H17: 2026-10-05 | J17: =IF(I17<>"", IF(I17>DATEVALUE(H17),"🔴 逾期 "&(I17-DATEVALUE(H17))&"天", IF(DATEVALUE(H17)>I17,"🟢 提前 "&(DATEVALUE(H17)-I17)&"天","🟡 準時完成")), IF((DATEVALUE(H17)-TODAY())<=3,"🟡 接近截止（"&(DATEVALUE(H17)-TODAY())&"天）", IF(TODAY()>DATEVALUE(H17),"🔴 逾期 "&(TODAY()-DATEVALUE(H17))&"天（未完成）","🟢 " &(DATEVALUE(H17)-TODAY())&"天後到期"))) | K17: 0
A18: 文件化與知識傳承
A19: 文件化與知識傳承 | B19: 文件更新 | C19: T4-Doc1 | D19: 設備預約SOP更新 | E19: 設備預約標準程序更新 | F19: 設備預約SOP | G19: Patty | H19: 2026-10-10 | J19: =IF(I19<>"", IF(I19>DATEVALUE(H19),"🔴 逾期 "&(I19-DATEVALUE(H19))&"天", IF(DATEVALUE(H19)>I19,"🟢 提前 "&(DATEVALUE(H19)-I19)&"天","🟡 準時完成")), IF((DATEVALUE(H19)-TODAY())<=3,"🟡 接近截止（"&(DATEVALUE(H19)-TODAY())&"天）", IF(TODAY()>DATEVALUE(H19),"🔴 逾期 "&(TODAY()-DATEVALUE(H19))&"天（未完成）","🟢 " &(DATEVALUE(H19)-TODAY())&"天後到期"))) | K19: 0
A20: 文件化與知識傳承 | B20: 文件編寫 | C20: T4-Doc2 | D20: FAQ編寫 | E20: 常見問題與解答編寫 | F20: FAQ文件 | G20: Patty | H20: 2026-10-12 | J20: =IF(I20<>"", IF(I20>DATEVALUE(H20),"🔴 逾期 "&(I20-DATEVALUE(H20))&"天", IF(DATEVALUE(H20)>I20,"🟢 提前 "&(DATEVALUE(H20)-I20)&"天","🟡 準時完成")), IF((DATEVALUE(H20)-TODAY())<=3,"🟡 接近截止（"&(DATEVALUE(H20)-TODAY())&"天）", IF(TODAY()>DATEVALUE(H20),"🔴 逾期 "&(TODAY()-DATEVALUE(H20))&"天（未完成）","🟢 " &(DATEVALUE(H20)-TODAY())&"天後到期"))) | K20: 0

Sheet T5開發計劃
A1: T5開發計劃｜KM資料庫優化
A2: 負責人：Patty, Anderson ｜ 建立日期：2026-07-31 | M2: ▸ 請填入實際檔案路徑或 SharePoint 連結 | N2: ▸ 本週的關鍵技術判斷？為什麼這樣決定？ | O2: ▸ 本週否決過AI的哪個建議？為什麼？
A3: 階段 | B3: 子階段 | C3: 任務編號 | D3: 任務名稱 | E3: 任務說明 | F3: 交付產出 | G3: 負責人 | H3: 預計完成日 | I3: 實際完成日 | J3: 開發狀態 | K3: 進度(%) | L3: 備註 | M3: 交付路徑 | N3: 關鍵判斷 | O3: 否決AI記錄
A4: 系統架構設計
A5: 系統架構設計 | B5: 架構規劃 | C5: T5-A1 | D5: 知識架構規劃 | E5: Neo4j/Qdrant混合知識架構規劃 | F5: 知識架構文件 | G5: Jimmy | H5: 2026-08-25 | J5: =IF(I5<>"", IF(I5>DATEVALUE(H5),"🔴 逾期 "&(I5-DATEVALUE(H5))&"天", IF(DATEVALUE(H5)>I5,"🟢 提前 "&(DATEVALUE(H5)-I5)&"天","🟡 準時完成")), IF((DATEVALUE(H5)-TODAY())<=3,"🟡 接近截止（"&(DATEVALUE(H5)-TODAY())&"天）", IF(TODAY()>DATEVALUE(H5),"🔴 逾期 "&(TODAY()-DATEVALUE(H5))&"天（未完成）","🟢 " &(DATEVALUE(H5)-TODAY())&"天後到期"))) | K5: 0
A6: 系統架構設計 | B6: 效能設計 | C6: T5-A2 | D6: 效能優化設計 | E6: 查詢效能優化架構設計 | F6: 效能優化方案文件 | G6: Anderson | H6: 2026-09-01 | J6: =IF(I6<>"", IF(I6>DATEVALUE(H6),"🔴 逾期 "&(I6-DATEVALUE(H6))&"天", IF(DATEVALUE(H6)>I6,"🟢 提前 "&(DATEVALUE(H6)-I6)&"天","🟡 準時完成")), IF((DATEVALUE(H6)-TODAY())<=3,"🟡 接近截止（"&(DATEVALUE(H6)-TODAY())&"天）", IF(TODAY()>DATEVALUE(H6),"🔴 逾期 "&(TODAY()-DATEVALUE(H6))&"天（未完成）","🟢 " &(DATEVALUE(H6)-TODAY())&"天後到期"))) | K6: 0
A7: 系統流程設計
A8: 系統流程設計 | B8: 流程設計 | C8: T5-B1 | D8: 知識入庫流程設計 | E8: 知識入庫審核流程設計 | F8: 知識入庫流程圖 | G8: Patty | H8: 2026-09-05 | J8: =IF(I8<>"", IF(I8>DATEVALUE(H8),"🔴 逾期 "&(I8-DATEVALUE(H8))&"天", IF(DATEVALUE(H8)>I8,"🟢 提前 "&(DATEVALUE(H8)-I8)&"天","🟡 準時完成")), IF((DATEVALUE(H8)-TODAY())<=3,"🟡 接近截止（"&(DATEVALUE(H8)-TODAY())&"天）", IF(TODAY()>DATEVALUE(H8),"🔴 逾期 "&(TODAY()-DATEVALUE(H8))&"天（未完成）","🟢 " &(DATEVALUE(H8)-TODAY())&"天後到期"))) | K8: 0
A9: 知識工程與需求訪談
A10: 知識工程與需求訪談 | B10: 需求訪談 | C10: T5-K1 | D10: 現有知識架構訪談 | E10: Jimmy/Patty現有知識架構訪談 | F10: 訪談紀錄與分析報告 | G10: Jimmy | H10: 2026-08-15 | J10: =IF(I10<>"", IF(I10>DATEVALUE(H10),"🔴 逾期 "&(I10-DATEVALUE(H10))&"天", IF(DATEVALUE(H10)>I10,"🟢 提前 "&(DATEVALUE(H10)-I10)&"天","🟡 準時完成")), IF((DATEVALUE(H10)-TODAY())<=3,"🟡 接近截止（"&(DATEVALUE(H10)-TODAY())&"天）", IF(TODAY()>DATEVALUE(H10),"🔴 逾期 "&(TODAY()-DATEVALUE(H10))&"天（未完成）","🟢 " &(DATEVALUE(H10)-TODAY())&"天後到期"))) | K10: 0
A11: 知識工程與需求訪談 | B11: 經驗收集 | C11: T5-K2 | D11: 專家經驗收集 | E11: Matt/Issa專家經驗收集 | F11: 專家經驗文件 | G11: Patty | H11: 2026-08-22 | J11: =IF(I11<>"", IF(I11>DATEVALUE(H11),"🔴 逾期 "&(I11-DATEVALUE(H11))&"天", IF(DATEVALUE(H11)>I11,"🟢 提前 "&(DATEVALUE(H11)-I11)&"天","🟡 準時完成")), IF((DATEVALUE(H11)-TODAY())<=3,"🟡 接近截止（"&(DATEVALUE(H11)-TODAY())&"天）", IF(TODAY()>DATEVALUE(H11),"🔴 逾期 "&(TODAY()-DATEVALUE(H11))&"天（未完成）","🟢 " &(DATEVALUE(H11)-TODAY())&"天後到期"))) | K11: 0
A12: 知識工程與需求訪談 | B12: 缺口分析 | C12: T5-K3 | D12: 知識缺口分析 | E12: 現有知識庫缺口分析 | F12: 知識缺口分析報告 | G12: Anderson | H12: 2026-08-28 | J12: =IF(I12<>"", IF(I12>DATEVALUE(H12),"🔴 逾期 "&(I12-DATEVALUE(H12))&"天", IF(DATEVALUE(H12)>I12,"🟢 提前 "&(DATEVALUE(H12)-I12)&"天","🟡 準時完成")), IF((DATEVALUE(H12)-TODAY())<=3,"🟡 接近截止（"&(DATEVALUE(H12)-TODAY())&"天）", IF(TODAY()>DATEVALUE(H12),"🔴 逾期 "&(TODAY()-DATEVALUE(H12))&"天（未完成）","🟢 " &(DATEVALUE(H12)-TODAY())&"天後到期"))) | K12: 0
A13: 開發現迭代任務
A14: 開發現迭代任務 | B14: 開發任務 | C14: T5-D1 | D14: Neo4j優化 | E14: Neo4j圖資料庫優化 | F14: 優化後Neo4j系統 | G14: Anderson | H14: 2026-09-10 | J14: =IF(I14<>"", IF(I14>DATEVALUE(H14),"🔴 逾期 "&(I14-DATEVALUE(H14))&"天", IF(DATEVALUE(H14)>I14,"🟢 提前 "&(DATEVALUE(H14)-I14)&"天","🟡 準時完成")), IF((DATEVALUE(H14)-TODAY())<=3,"🟡 接近截止（"&(DATEVALUE(H14)-TODAY())&"天）", IF(TODAY()>DATEVALUE(H14),"🔴 逾期 "&(TODAY()-DATEVALUE(H14))&"天（未完成）","🟢 " &(DATEVALUE(H14)-TODAY())&"天後到期"))) | K14: 0
A15: 開發現迭代任務 | B15: 開發任務 | C15: T5-D2 | D15: Qdrant優化 | E15: Qdrant向量檢索優化 | F15: 優化後Qdrant系統 | G15: Patty | H15: 2026-09-15 | J15: =IF(I15<>"", IF(I15>DATEVALUE(H15),"🔴 逾期 "&(I15-DATEVALUE(H15))&"天", IF(DATEVALUE(H15)>I15,"🟢 提前 "&(DATEVALUE(H15)-I15)&"天","🟡 準時完成")), IF((DATEVALUE(H15)-TODAY())<=3,"🟡 接近截止（"&(DATEVALUE(H15)-TODAY())&"天）", IF(TODAY()>DATEVALUE(H15),"🔴 逾期 "&(TODAY()-DATEVALUE(H15))&"天（未完成）","🟢 " &(DATEVALUE(H15)-TODAY())&"天後到期"))) | K15: 0
A16: 開發現迭代任務 | B16: 開發任務 | C16: T5-D3 | D16: 系統整合 | E16: Neo4j/Qdrant整合串接 | F16: 整合測試報告 | G16: Anderson | H16: 2026-09-22 | J16: =IF(I16<>"", IF(I16>DATEVALUE(H16),"🔴 逾期 "&(I16-DATEVALUE(H16))&"天", IF(DATEVALUE(H16)>I16,"🟢 提前 "&(DATEVALUE(H16)-I16)&"天","🟡 準時完成")), IF((DATEVALUE(H16)-TODAY())<=3,"🟡 接近截止（"&(DATEVALUE(H16)-TODAY())&"天）", IF(TODAY()>DATEVALUE(H16),"🔴 逾期 "&(TODAY()-DATEVALUE(H16))&"天（未完成）","🟢 " &(DATEVALUE(H16)-TODAY())&"天後到期"))) | K16: 0
A17: 系統整合測試
A18: 系統整合測試 | B18: 測試 | C18: T5-T1 | D18: 效能測試 | E18: 優化後系統效能測試 | F18: 效能測試報告 | G18: Anderson | H18: 2026-09-28 | J18: =IF(I18<>"", IF(I18>DATEVALUE(H18),"🔴 逾期 "&(I18-DATEVALUE(H18))&"天", IF(DATEVALUE(H18)>I18,"🟢 提前 "&(DATEVALUE(H18)-I18)&"天","🟡 準時完成")), IF((DATEVALUE(H18)-TODAY())<=3,"🟡 接近截止（"&(DATEVALUE(H18)-TODAY())&"天）", IF(TODAY()>DATEVALUE(H18),"🔴 逾期 "&(TODAY()-DATEVALUE(H18))&"天（未完成）","🟢 " &(DATEVALUE(H18)-TODAY())&"天後到期"))) | K18: 0
A19: 驗收交付標準
A20: 驗收交付標準 | B20: 驗收 | C20: T5-V1 | D20: 效能驗收 | E20: 查詢效能達標驗收 | F20: 驗收確認書 | G20: Patty | H20: 2026-10-05 | J20: =IF(I20<>"", IF(I20>DATEVALUE(H20),"🔴 逾期 "&(I20-DATEVALUE(H20))&"天", IF(DATEVALUE(H20)>I20,"🟢 提前 "&(DATEVALUE(H20)-I20)&"天","🟡 準時完成")), IF((DATEVALUE(H20)-TODAY())<=3,"🟡 接近截止（"&(DATEVALUE(H20)-TODAY())&"天）", IF(TODAY()>DATEVALUE(H20),"🔴 逾期 "&(TODAY()-DATEVALUE(H20))&"天（未完成）","🟢 " &(DATEVALUE(H20)-TODAY())&"天後到期"))) | K20: 0
A21: 文件化與知識傳承
A22: 文件化與知識傳承 | B22: 文件編寫 | C22: T5-Doc1 | D22: Neo4j知識圖譜操作手冊 | E22: Neo4j操作與維護手冊 | F22: Neo4j操作手冊 | G22: Anderson | H22: 2026-10-10 | J22: =IF(I22<>"", IF(I22>DATEVALUE(H22),"🔴 逾期 "&(I22-DATEVALUE(H22))&"天", IF(DATEVALUE(H22)>I22,"🟢 提前 "&(DATEVALUE(H22)-I22)&"天","🟡 準時完成")), IF((DATEVALUE(H22)-TODAY())<=3,"🟡 接近截止（"&(DATEVALUE(H22)-TODAY())&"天）", IF(TODAY()>DATEVALUE(H22),"🔴 逾期 "&(TODAY()-DATEVALUE(H22))&"天（未完成）","🟢 " &(DATEVALUE(H22)-TODAY())&"天後到期"))) | K22: 0
A23: 文件化與知識傳承 | B23: 文件編寫 | C23: T5-Doc2 | D23: Qdrant向量檢索操作手冊 | E23: Qdrant操作與維護手冊 | F23: Qdrant操作手冊 | G23: Patty | H23: 2026-10-12 | J23: =IF(I23<>"", IF(I23>DATEVALUE(H23),"🔴 逾期 "&(I23-DATEVALUE(H23))&"天", IF(DATEVALUE(H23)>I23,"🟢 提前 "&(DATEVALUE(H23)-I23)&"天","🟡 準時完成")), IF((DATEVALUE(H23)-TODAY())<=3,"🟡 接近截止（"&(DATEVALUE(H23)-TODAY())&"天）", IF(TODAY()>DATEVALUE(H23),"🔴 逾期 "&(TODAY()-DATEVALUE(H23))&"天（未完成）","🟢 " &(DATEVALUE(H23)-TODAY())&"天後到期"))) | K23: 0
A24: 文件化與知識傳承 | B24: 文件編寫 | C24: T5-Doc3 | D24: 知識貢獻SOP | E24: 知識入庫與貢獻標準程序 | F24: 知識貢獻SOP | G24: Jimmy | H24: 2026-10-15 | J24: =IF(I24<>"", IF(I24>DATEVALUE(H24),"🔴 逾期 "&(I24-DATEVALUE(H24))&"天", IF(DATEVALUE(H24)>I24,"🟢 提前 "&(DATEVALUE(H24)-I24)&"天","🟡 準時完成")), IF((DATEVALUE(H24)-TODAY())<=3,"🟡 接近截止（"&(DATEVALUE(H24)-TODAY())&"天）", IF(TODAY()>DATEVALUE(H24),"🔴 逾期 "&(TODAY()-DATEVALUE(H24))&"天（未完成）","🟢 " &(DATEVALUE(H24)-TODAY())&"天後到期"))) | K24: 0

Sheet T6開發計劃
A1: T6開發計劃｜LLM選型
A2: 負責人：Jimmy, Alf ｜ 建立日期：2026-07-31 | M2: ▸ 請填入實際檔案路徑或 SharePoint 連結 | N2: ▸ 本週的關鍵技術判斷？為什麼這樣決定？ | O2: ▸ 本週否決過AI的哪個建議？為什麼？
A3: 階段 | B3: 子階段 | C3: 任務編號 | D3: 任務名稱 | E3: 任務說明 | F3: 交付產出 | G3: 負責人 | H3: 預計完成日 | I3: 實際完成日 | J3: 開發狀態 | K3: 進度(%) | L3: 備註 | M3: 交付路徑 | N3: 關鍵判斷 | O3: 否決AI記錄
A4: 系統架構設計
A5: 系統架構設計 | B5: 架構規劃 | C5: T6-A1 | D5: 評估架構設計 | E5: LLM評估指標與架構設計 | F5: 評估架構文件 | G5: Jimmy | H5: 2026-08-20 | J5: =IF(I5<>"", IF(I5>DATEVALUE(H5),"🔴 逾期 "&(I5-DATEVALUE(H5))&"天", IF(DATEVALUE(H5)>I5,"🟢 提前 "&(DATEVALUE(H5)-I5)&"天","🟡 準時完成")), IF((DATEVALUE(H5)-TODAY())<=3,"🟡 接近截止（"&(DATEVALUE(H5)-TODAY())&"天）", IF(TODAY()>DATEVALUE(H5),"🔴 逾期 "&(TODAY()-DATEVALUE(H5))&"天（未完成）","🟢 " &(DATEVALUE(H5)-TODAY())&"天後到期"))) | K5: 0
A6: 系統流程設計
A7: 系統流程設計 | B7: 流程設計 | C7: T6-B1 | D7: 評估流程設計 | E7: LLM候選模型評估流程設計 | F7: 評估流程圖 | G7: Jimmy | H7: 2026-08-25 | J7: =IF(I7<>"", IF(I7>DATEVALUE(H7),"🔴 逾期 "&(I7-DATEVALUE(H7))&"天", IF(DATEVALUE(H7)>I7,"🟢 提前 "&(DATEVALUE(H7)-I7)&"天","🟡 準時完成")), IF((DATEVALUE(H7)-TODAY())<=3,"🟡 接近截止（"&(DATEVALUE(H7)-TODAY())&"天）", IF(TODAY()>DATEVALUE(H7),"🔴 逾期 "&(TODAY()-DATEVALUE(H7))&"天（未完成）","🟢 " &(DATEVALUE(H7)-TODAY())&"天後到期"))) | K7: 0
A8: 知識工程與需求訪談
A9: 知識工程與需求訪談 | B9: 需求訪談 | C9: T6-K1 | D9: 評估指標訪談 | E9: Sam/主管評估指標訪談 | F9: 訪談紀錄 | G9: Jimmy | H9: 2026-08-15 | J9: =IF(I9<>"", IF(I9>DATEVALUE(H9),"🔴 逾期 "&(I9-DATEVALUE(H9))&"天", IF(DATEVALUE(H9)>I9,"🟢 提前 "&(DATEVALUE(H9)-I9)&"天","🟡 準時完成")), IF((DATEVALUE(H9)-TODAY())<=3,"🟡 接近截止（"&(DATEVALUE(H9)-TODAY())&"天）", IF(TODAY()>DATEVALUE(H9),"🔴 逾期 "&(TODAY()-DATEVALUE(H9))&"天（未完成）","🟢 " &(DATEVALUE(H9)-TODAY())&"天後到期"))) | K9: 0
A10: 知識工程與需求訪談 | B10: 文件收集 | C10: T6-K2 | D10: 候選模型文件收集 | E10: 收集各候選LLM模型技術文件 | F10: 模型技術文件彙整 | G10: Alf | H10: 2026-08-20 | J10: =IF(I10<>"", IF(I10>DATEVALUE(H10),"🔴 逾期 "&(I10-DATEVALUE(H10))&"天", IF(DATEVALUE(H10)>I10,"🟢 提前 "&(DATEVALUE(H10)-I10)&"天","🟡 準時完成")), IF((DATEVALUE(H10)-TODAY())<=3,"🟡 接近截止（"&(DATEVALUE(H10)-TODAY())&"天）", IF(TODAY()>DATEVALUE(H10),"🔴 逾期 "&(TODAY()-DATEVALUE(H10))&"天（未完成）","🟢 " &(DATEVALUE(H10)-TODAY())&"天後到期"))) | K10: 0
A11: 知識工程與需求訪談 | B11: 情境訪談 | C11: T6-K3 | D11: 使用情境訪談 | E11: 各單位LLM使用情境訪談 | F11: 使用情境分析報告 | G11: Jimmy | H11: 2026-08-25 | J11: =IF(I11<>"", IF(I11>DATEVALUE(H11),"🔴 逾期 "&(I11-DATEVALUE(H11))&"天", IF(DATEVALUE(H11)>I11,"🟢 提前 "&(DATEVALUE(H11)-I11)&"天","🟡 準時完成")), IF((DATEVALUE(H11)-TODAY())<=3,"🟡 接近截止（"&(DATEVALUE(H11)-TODAY())&"天）", IF(TODAY()>DATEVALUE(H11),"🔴 逾期 "&(TODAY()-DATEVALUE(H11))&"天（未完成）","🟢 " &(DATEVALUE(H11)-TODAY())&"天後到期"))) | K11: 0
A12: 開發現迭代任務
A13: 開發現迭代任務 | B13: 評測任務 | C13: T6-D1 | D13: 模型評測 | E13: 候選LLM模型基準測試 | F13: 評測結果數據 | G13: Alf | H13: 2026-09-10 | J13: =IF(I13<>"", IF(I13>DATEVALUE(H13),"🔴 逾期 "&(I13-DATEVALUE(H13))&"天", IF(DATEVALUE(H13)>I13,"🟢 提前 "&(DATEVALUE(H13)-I13)&"天","🟡 準時完成")), IF((DATEVALUE(H13)-TODAY())<=3,"🟡 接近截止（"&(DATEVALUE(H13)-TODAY())&"天）", IF(TODAY()>DATEVALUE(H13),"🔴 逾期 "&(TODAY()-DATEVALUE(H13))&"天（未完成）","🟢 " &(DATEVALUE(H13)-TODAY())&"天後到期"))) | K13: 0
A14: 開發現迭代任務 | B14: 評估任務 | C14: T6-D2 | D14: 綜合評估 | E14: 多維度綜合評估分析 | F14: 評估分析報告 | G14: Jimmy | H14: 2026-09-18 | J14: =IF(I14<>"", IF(I14>DATEVALUE(H14),"🔴 逾期 "&(I14-DATEVALUE(H14))&"天", IF(DATEVALUE(H14)>I14,"🟢 提前 "&(DATEVALUE(H14)-I14)&"天","🟡 準時完成")), IF((DATEVALUE(H14)-TODAY())<=3,"🟡 接近截止（"&(DATEVALUE(H14)-TODAY())&"天）", IF(TODAY()>DATEVALUE(H14),"🔴 逾期 "&(TODAY()-DATEVALUE(H14))&"天（未完成）","🟢 " &(DATEVALUE(H14)-TODAY())&"天後到期"))) | K14: 0
A15: 系統整合測試
A16: 系統整合測試 | B16: 測試 | C16: T6-T1 | D16: 評估報告審查 | E16: LLM評估報告審查會議 | F16: 審查會議紀錄 | G16: Sam | H16: 2026-09-25 | J16: =IF(I16<>"", IF(I16>DATEVALUE(H16),"🔴 逾期 "&(I16-DATEVALUE(H16))&"天", IF(DATEVALUE(H16)>I16,"🟢 提前 "&(DATEVALUE(H16)-I16)&"天","🟡 準時完成")), IF((DATEVALUE(H16)-TODAY())<=3,"🟡 接近截止（"&(DATEVALUE(H16)-TODAY())&"天）", IF(TODAY()>DATEVALUE(H16),"🔴 逾期 "&(TODAY()-DATEVALUE(H16))&"天（未完成）","🟢 " &(DATEVALUE(H16)-TODAY())&"天後到期"))) | K16: 0
A17: 驗收交付標準
A18: 驗收交付標準 | B18: 驗收 | C18: T6-V1 | D18: 評估報告驗收 | E18: LLM評估報告驗收確認 | F18: 驗收確認書 | G18: Sam | H18: 2026-10-02 | J18: =IF(I18<>"", IF(I18>DATEVALUE(H18),"🔴 逾期 "&(I18-DATEVALUE(H18))&"天", IF(DATEVALUE(H18)>I18,"🟢 提前 "&(DATEVALUE(H18)-I18)&"天","🟡 準時完成")), IF((DATEVALUE(H18)-TODAY())<=3,"🟡 接近截止（"&(DATEVALUE(H18)-TODAY())&"天）", IF(TODAY()>DATEVALUE(H18),"🔴 逾期 "&(TODAY()-DATEVALUE(H18))&"天（未完成）","🟢 " &(DATEVALUE(H18)-TODAY())&"天後到期"))) | K18: 0
A19: 文件化與知識傳承
A20: 文件化與知識傳承 | B20: 文件編寫 | C20: T6-Doc1 | D20: LLM評估報告 | E20: LLM選型評估完整報告 | F20: LLM評估報告文件 | G20: Jimmy | H20: 2026-10-08 | J20: =IF(I20<>"", IF(I20>DATEVALUE(H20),"🔴 逾期 "&(I20-DATEVALUE(H20))&"天", IF(DATEVALUE(H20)>I20,"🟢 提前 "&(DATEVALUE(H20)-I20)&"天","🟡 準時完成")), IF((DATEVALUE(H20)-TODAY())<=3,"🟡 接近截止（"&(DATEVALUE(H20)-TODAY())&"天）", IF(TODAY()>DATEVALUE(H20),"🔴 逾期 "&(TODAY()-DATEVALUE(H20))&"天（未完成）","🟢 " &(DATEVALUE(H20)-TODAY())&"天後到期"))) | K20: 0
A21: 文件化與知識傳承 | B21: 文件編寫 | C21: T6-Doc2 | D21: 選型建議書 | E21: LLM最終選型建議書 | F21: 選型建議書 | G21: Alf | H21: 2026-10-12 | J21: =IF(I21<>"", IF(I21>DATEVALUE(H21),"🔴 逾期 "&(I21-DATEVALUE(H21))&"天", IF(DATEVALUE(H21)>I21,"🟢 提前 "&(DATEVALUE(H21)-I21)&"天","🟡 準時完成")), IF((DATEVALUE(H21)-TODAY())<=3,"🟡 接近截止（"&(DATEVALUE(H21)-TODAY())&"天）", IF(TODAY()>DATEVALUE(H21),"🔴 逾期 "&(TODAY()-DATEVALUE(H21))&"天（未完成）","🟢 " &(DATEVALUE(H21)-TODAY())&"天後到期"))) | K21: 0

Sheet T7開發計劃
A1: T7 評估openVitamin功能分析與引進計劃 ｜ 專業軟體開發顧問框架 ｜ 2026 July
A2: 建立：2026-07-31 負責：Alf, Jimmy ｜ 專業顧問框架：系統架構設計 → 系統流程設計 → 知識工程與需求訪談 → 開發現迭代任務 → 系統整合測試 → 驗收交付標準 → 文件化與知識傳承 ｜ 請填寫I欄與K欄 | M2: ▸ 請填入實際檔案路徑或 SharePoint 連結 | N2: ▸ 本週的關鍵技術判斷？為什麼這樣決定？ | O2: ▸ 本週否決過AI的哪個建議？為什麼？
A3: 階段 | B3: 子階段 | C3: 任務編號 | D3: 任務名稱 | E3: 任務說明 | F3: 交付產出 | G3: 負責人 | H3: 預計完成日 | I3: 實際完成日 | J3: 開發狀態 | K3: 進度(%) | L3: 備註 | M3: 交付路徑 | N3: 關鍵判斷 | O3: 否決AI記錄
A4: Phase 1｜系統架構設計
A5: 系統架構設計 | B5: 系統功能分析 | C5: T7-01 | D5: OpenVitamin 系統功能模組分析 | E5: 依據 v4/v2/V10/V20 報告，分析系統功能模組、API界面、資料流、Plugin擴充機制 | F5: 系統功能分析報告_v5（更新整合版） | G5: Alf | H5: 2026-08-08 | J5: =IF(I5<>"",IF(I5>DATEVALUE(H5),"[Red] Overdue by " & (I5-DATEVALUE(H5)) & " days",IF(DATEVALUE(H5)>I5,"[Green] Early by " & (DATEVALUE(H5)-I5) & " days","[Yellow] On Time")),IF((DATEVALUE(H5)-TODAY())<=3,"[Yellow] Due in " & (DATEVALUE(H5)-TODAY()) & " days",IF(TODAY()>DATEVALUE(H5),"[Red] Overdue - Not Completed","[Green] " & (DATEVALUE(H5)-TODAY()) & " days to due"))) | K5: 60 | L5: 需整合所有版本
A6: 系統架構設計 | B6: 原生架構分析 | C6: T7-02 | D6: OpenVitamin 原生架構深度分析 | E6: 分析核心引擎、Plugin機制、數據隔離架構、安全模型、擴充性 | F6: 原生架構分析報告_v3 | G6: Alf | H6: 2026-08-12 | J6: =IF(I6<>"",IF(I6>DATEVALUE(H6),"[Red] Overdue by " & (I6-DATEVALUE(H6)) & " days",IF(DATEVALUE(H6)>I6,"[Green] Early by " & (DATEVALUE(H6)-I6) & " days","[Yellow] On Time")),IF((DATEVALUE(H6)-TODAY())<=3,"[Yellow] Due in " & (DATEVALUE(H6)-TODAY()) & " days",IF(TODAY()>DATEVALUE(H6),"[Red] Overdue - Not Completed","[Green] " & (DATEVALUE(H6)-TODAY()) & " days to due"))) | K6: 50
A7: 系統架構設計 | B7: 整合架構規劃 | C7: T7-03 | D7: 與內部系統整合架構規劃 | E7: 評估與 Amarisoft gNB、Anritsu MT8000A、Neo4j、Qdrant 的整合點 | F7: 整合架構規劃文件 | G7: Alf | H7: 2026-08-15 | J7: =IF(I7<>"",IF(I7>DATEVALUE(H7),"[Red] Overdue by " & (I7-DATEVALUE(H7)) & " days",IF(DATEVALUE(H7)>I7,"[Green] Early by " & (DATEVALUE(H7)-I7) & " days","[Yellow] On Time")),IF((DATEVALUE(H7)-TODAY())<=3,"[Yellow] Due in " & (DATEVALUE(H7)-TODAY()) & " days",IF(TODAY()>DATEVALUE(H7),"[Red] Overdue - Not Completed","[Green] " & (DATEVALUE(H7)-TODAY()) & " days to due"))) | K7: 50 | L7: 需與 Anderson 確認接口
A8: 系統架構設計 | B8: 比較架構分析 | C8: T7-04 | D8: OpenVitamin vs 未來幢平台 vs 自建方案架構比較 | E8: 從技術可行性、擴充性、維運成本、Vendor Lock-in 角度進行三方案架構比較 | F8: 三方案架構比較分析報告 | G8: Alf | H8: 2026-08-19 | J8: =IF(I8<>"",IF(I8>DATEVALUE(H8),"[Red] Overdue by " & (I8-DATEVALUE(H8)) & " days",IF(DATEVALUE(H8)>I8,"[Green] Early by " & (DATEVALUE(H8)-I8) & " days","[Yellow] On Time")),IF((DATEVALUE(H8)-TODAY())<=3,"[Yellow] Due in " & (DATEVALUE(H8)-TODAY()) & " days",IF(TODAY()>DATEVALUE(H8),"[Red] Overdue - Not Completed","[Green] " & (DATEVALUE(H8)-TODAY()) & " days to due"))) | K8: 40 | L8: 為主管決策提供技術依據
A10: Phase 2｜系統流程設計
A11: 系統流程設計 | B11: 應用場景流程 | C11: T7-05 | D11: 五大應用場景流程設計 | E11: 依據 V20 報告，設計5大應用場景（知識檢索/文件生成/決策輔助/異常分析/系統整合）標準流程 | F11: 應用場景流程圖_v2 | G11: Alf | H11: 2026-08-15 | J11: =IF(I11<>"",IF(I11>DATEVALUE(H11),"[Red] Overdue by " & (I11-DATEVALUE(H11)) & " days",IF(DATEVALUE(H11)>I11,"[Green] Early by " & (DATEVALUE(H11)-I11) & " days","[Yellow] On Time")),IF((DATEVALUE(H11)-TODAY())<=3,"[Yellow] Due in " & (DATEVALUE(H11)-TODAY()) & " days",IF(TODAY()>DATEVALUE(H11),"[Red] Overdue - Not Completed","[Green] " & (DATEVALUE(H11)-TODAY()) & " days to due"))) | K11: 60 | L11: 需與 Jimmy 確認設備端串接流程
A12: 系統流程設計 | B12: 技術對接流程 | C12: T7-06 | D12: OpenVitamin 與設備端技術對接流程 | E12: 設計 OpenVitamin 與 Amarisoft REST API、Anritsu SCPI 的技術對接流程（含錯誤處理） | F12: 技術對接流程圖 | G12: Jimmy | H12: 2026-08-12 | J12: =IF(I12<>"",IF(I12>DATEVALUE(H12),"[Red] Overdue by " & (I12-DATEVALUE(H12)) & " days",IF(DATEVALUE(H12)>I12,"[Green] Early by " & (DATEVALUE(H12)-I12) & " days","[Yellow] On Time")),IF((DATEVALUE(H12)-TODAY())<=3,"[Yellow] Due in " & (DATEVALUE(H12)-TODAY()) & " days",IF(TODAY()>DATEVALUE(H12),"[Red] Overdue - Not Completed","[Green] " & (DATEVALUE(H12)-TODAY()) & " days to due"))) | K12: 50 | L12: Jimmy 負責
A13: 系統流程設計 | B13: API缺口分析 | C13: T7-07 | D13: API 缺口分析與 Bridging 方案設計 | E13: 盤點 OpenVitamin API 與內部需求缺口，設計 Bridging 中間件方案 | F13: API缺口分析報告 + Bridging方案 | G13: Jimmy | H13: 2026-08-12 | J13: =IF(I13<>"",IF(I13>DATEVALUE(H13),"[Red] Overdue by " & (I13-DATEVALUE(H13)) & " days",IF(DATEVALUE(H13)>I13,"[Green] Early by " & (DATEVALUE(H13)-I13) & " days","[Yellow] On Time")),IF((DATEVALUE(H13)-TODAY())<=3,"[Yellow] Due in " & (DATEVALUE(H13)-TODAY()) & " days",IF(TODAY()>DATEVALUE(H13),"[Red] Overdue - Not Completed","[Green] " & (DATEVALUE(H13)-TODAY()) & " days to due"))) | K13: 50 | L13: Jimmy 負責
A14: 系統流程設計 | B14: 評估決策流程 | C14: T7-08 | D14: 主管決策審查流程設計 | E14: 設計從評估結果 → 分析報告 → 引進建議 → 主管核准 → POC 啟動的完整決策流程 | F14: 主管決策審查流程圖 | G14: Alf | H14: 2026-08-26 | J14: =IF(I14<>"",IF(I14>DATEVALUE(H14),"[Red] Overdue by " & (I14-DATEVALUE(H14)) & " days",IF(DATEVALUE(H14)>I14,"[Green] Early by " & (DATEVALUE(H14)-I14) & " days","[Yellow] On Time")),IF((DATEVALUE(H14)-TODAY())<=3,"[Yellow] Due in " & (DATEVALUE(H14)-TODAY()) & " days",IF(TODAY()>DATEVALUE(H14),"[Red] Overdue - Not Completed","[Green] " & (DATEVALUE(H14)-TODAY()) & " days to due"))) | K14: 40
A16: Phase 3｜知識工程與需求訪談 ★ AI Agent 核心基礎
